Workbook

Sheet EZRAB_README
A1: EZRAB VOLUME CALCULATOR MASTER | B1: Reference + calculation specification for EZRAB AI Agent
A2: Purpose | B2: Master workbook for the 19 construction volume calculators contained in the supplied RAB workbook.
A3: Important | B3: The original calculation sheets are preserved so the AI agent can inspect their exact formulas, input cells, outputs, and embedded reference images.
A4: Production rule | B4: Do NOT silently convert calculation errors to zero. Validate inputs first; surface calculation errors to the user.
A5: Precision | B5: Keep internal calculation precision at least 6 decimal places. Round only for display/export unless a construction rule explicitly requires ROUNDUP/rounding.
A6: Unit rule | B6: Store a canonical unit for every parameter and convert explicitly before calculation. Never mix cm, mm, m, m², m³ without conversion.
A7: Dependency rule | B7: Volume Calculator → QTO → RAB → AHSP → Price → Rekap/BOQ → Kurva S → Laporan.
A8: AI rule | B8: AI may propose calculator actions, but the deterministic calculation engine must execute and validate formulas. AI must never invent coefficients, prices, units, or AHSP codes.
A9: Input rule | B9: Only marked input cells are user-editable. Formula/result cells are read-only in the web UI.
A10: Audit rule | B10: Every calculated result must retain formula_id, input snapshot, unit, precision, timestamp, and source calculator.

Sheet Bowplank
D3: AHSP S.E. BHINA KONSTRUKSI NO. 30 TAHUN 2025
B5: 1. | C5: PEKERJAAN PEMBERSIHAN & BOWPLANK
B7: 1.1 | C7: Dimensi Utama | F7: 1.2 | G7: Volume | L7: 1.3 | M7: Result
C8: Ukuran lahan | G8: Volume pekerjaan bowplank | M8: Uraian | O8: Volume | P8: Satuan | Q8: Harga Satuan (Rp) | R8: Jumlah Harga (Rp)
B9: P | C9: Panjang lahan | D9: 0 | E9: m | F9: Luas pembersihan lahan | I9: =IFERROR(D9*D10,0) | J9: m² | L9: 1 | M9: Pekerja | O9: =IFERROR(H44+H55,0) | P9: OH | Q9: 100000 | R9: =IFERROR((Q9*O9)*L9,0)
B10: L | C10: Lebar lahan | D10: 0 | E10: m | F10: Keliling bowplank | I10: =IFERROR(2*(D9+D10+2*D11),0) | J10: m¹ | L10: 1 | M10: Tukang | O10: =H45 | P10: OH | Q10: 145000 | R10: =IFERROR((Q10*O10)*L10,0)
B11: C | C11: Jarak bebas plank | D11: 0 | E11: m | F11: Kebutuhan Patok bowplank | I11: =(I10/D13+1)*(D12+0.3)*105% | J11: m¹ | L11: 1 | M11: Kepala Tukang | O11: =H46 | P11: OH | Q11: 175000 | R11: =IFERROR((Q11*O11)*L11,0)
B12: H | C12: Tinggi patok | D12: 0 | E12: m | F12: Kebutuhan papan bowplank | I12: =I10*105% | J12: m¹ | L12: 1 | M12: Mandor | O12: =IFERROR(H47+H56,0) | P12: OH | Q12: 200000 | R12: =IFERROR((Q12*O12)*L12,0)
B13: R | C13: Jarak patok | D13: 0 | E13: m | F13: Kebutuhan penguat bowplank | I13: =(0.5*D12*2)*(I10/D13)/2*105% | J13: m¹ | O13: Jumlah Harga Tenaga Kerja = | R13: =SUM(R9:R12)
M14: BAHAN
M15: =C49 | O15: =H49 | P15: m³ | Q15: 3200000 | R15: =IFERROR(Q15*O15,0)
M16: =C50 | O16: =H50 | P16: m³ | Q16: 3000000 | R16: =IFERROR(Q16*O16,0)
M17: =C51 | O17: =H51 | P17: kg | Q17: 18000 | R17: =IFERROR(Q17*O17,0)
O18: Jumlah Harga Bahan = | R18: =SUM(R15:R17)
C19: Panduan Gambar: | Q19: TOTAL | R19: =IFERROR(R13+R18,0)
R20: Biaya Pekerjaan
C39: AHSP S.E. DIRJEN BHINA KONSTRUKSI NO. 30 TAHUN 2025
C41: Pemsangan 1 m' bouwplank
C42: Uraian | D42: Koefisien | E42: Sat.
C43: TENAGA KERJA
C44: Pekerja | D44: 0.012 | E44: OH | H44: =IFERROR(I10*D44,0)
C45: Tukang kayu | D45: 0.006 | E45: OH | H45: =IFERROR(I10*D45,0)
C46: Kepala tukang | D46: 0.0006 | E46: OH | H46: =IFERROR(I10*D46,0)
C47: Mandor | D47: 0.0012 | E47: OH | H47: =IFERROR(I10*D47,0)
C48: BAHAN
C49: Kaso 5/7 | D49: 0.013 | E49: m3 | H49: =IFERROR(0.0045*(I11+I13),0)
C50: Kayu papan 3/20 cm | D50: 0.007 | E50: m3 | H50: =IFERROR(I12*D50,0)
C51: Paku 2 inch | D51: 0.02 | E51: kg | H51: =IFERROR(I10*D51,0)
C53: 1 m2 Pembersihan dan pengupasan permukaan tanah (striping) s.d. tanaman ∅ 2 cm
C54: TENAGA KERJA
C55: Pekerja | D55: 0.1 | E55: OH | H55: =IFERROR(I9*D55,0)
C56: Mandor | D56: 0.005 | E56: OH | H56: =IFERROR(I9*D56,0)

Sheet Pondasi
D3: AHSP S.E. BHINA KONSTRUKSI NO. 30 TAHUN 2025
B5: 2. | C5: PEKERJAAN PEMASANGAN PONDASI BATU BELAH
B7: 2.1 | C7: Dimensi Utama | F7: 2.2 | G7: Volume | L7: 2.3 | M7: Result
C8: Galian tanah pondasi | G8: Volume pekerjaan pondasi | M8: Uraian | O8: Volume | P8: Satuan | Q8: Harga Satuan (Rp) | R8: Jumlah Harga (Rp)
B9: a.1 | C9: Lebar atas galian | D9: 0 | E9: m | G9: Volume galian | I9: =IF(D9=D10,SUM((D9*D11)*D12),SUM((D9+D10)/2)*D11*D12) | J9: m³ | L9: 1 | M9: Pekerja | O9: =I71 | P9: OH | Q9: 100000 | R9: =IFERROR((Q9*O9)*L9,0)
B10: b.1 | C10: Lebar bawah galian | D10: 0 | E10: m | G10: Volume pondasi | I10: =IF(D14=D15,SUM((D14*D16)*D12),SUM((D14+D15)/2)*D16*D12) | J10: m³ | L10: 1 | M10: Tukang | O10: =I72 | P10: OH | Q10: 145000 | R10: =IFERROR((Q10*O10)*L10,0)
B11: c.1 | C11: Dalam galian | D11: 0 | E11: m | G11: Pas. Aanstamping | I11: =IFERROR(D12*D10*D17,0) | J11: m³ | L11: 1 | M11: Kepala Tukang | O11: =I73 | P11: OH | Q11: 175000 | R11: =IFERROR((Q11*O11)*L11,0)
B12: P | C12: Panjang pondasi | D12: 0 | E12: m | G12: Pasir uruk | I12: =IFERROR(D10*D18*D12,0) | J12: m³ | L12: 1 | M12: Mandor | O12: =I74 | P12: OH | Q12: 200000 | R12: =IFERROR((Q12*O12)*L12,0)
C13: Pasangan pondasi | O13: Jumlah Harga Tenaga Kerja = | R13: =SUM(R9:R12)
B14: a.2 | C14: Lebar atas pondasi | D14: 0 | E14: m | G14: Volume pekerjaan urukan | M14: BAHAN
B15: b.2 | C15: Lebar bawah pondasi | D15: 0 | E15: m | F15: Urukan tanah di bawah lantai | I15: =IFERROR(D22*D23*D20,0) | J15: m³ | M15: Pasir uruk | O15: =I12 | P15: m³ | Q15: 254700 | R15: =IFERROR(Q15*O15,0)
B16: c.2 | C16: Tingg pondasi | D16: 0 | E16: m | F16: Urukan di samping pondasi | I16: =IFERROR(D21*I9,0) | J16: m³ | M16: Tanah uruk biasa | O16: =H116 | P16: m³ | Q16: 146900 | R16: =IFERROR(Q16*O16,0)
B17: d | C17: Tinggi batu kosong | D17: 0 | E17: m | F17: Urukan tanah kembali | I17: =I9 | J17: m³ | M17: Batu belah anstamping | O17: =H76 | P17: m³ | Q17: 286500 | R17: =IFERROR(Q17*O17,0)
B18: e | C18: Tinggi pasir uruk | D18: 0 | E18: m | L18: 1 | M18: BAHAN PASANGAN PONDASI CAMPURAN 1SP : 3PP
C19: Pekerjaan urukan | M19: =C85 | O19: =H85 | P19: m³ | Q19: 286500 | R19: =IFERROR(Q19*O19,0)
B20: f | C20: Tebal urukan di bawah lantai | D20: 0.4 | E20: m | M20: =C86 | O20: =H86 | P20: sak | Q20: 65000 | R20: =IFERROR(Q20*O20,0)
C21: Urukan samping pondasi | D21: 0.25 | E21: % | M21: =C87 | O21: =H87 | P21: m³ | Q21: 275000 | R21: =IFERROR(Q21*O21,0)
C22: Panjang bangunan | D22: 9 | E22: m | L22: 0 | M22: BAHAN PASANGAN PONDASI CAMPURAN 1SP : 4PP
C23: Lebar Bangunan | D23: 6 | E23: m | M23: =C95 | O23: =H95 | P23: m³ | Q23: 286500 | R23: =IFERROR(Q23*O23,0)
M24: =C96 | O24: =H96 | P24: sak | Q24: 65000 | R24: =IFERROR(Q24*O24,0)
M25: =C97 | O25: =H97 | P25: m³ | Q25: 275000 | R25: =IFERROR(Q25*O25,0)
O26: Jumlah Harga Bahan = | R26: =IFERROR(R15+R16+R17+R19+R20+R21+R23+R24+R25,0)
Q27: TOTAL | R27: =IFERROR(R26+R13,0)
R28: Biaya Pekerjaan
C41: Panduan Gambar:
C61: AHSP S.E. DIRJEN BHINA KONSTRUKSI NO. 30 TAHUN 2025
C63: 1 m3 galian tanah biasa sedalam 0 s.d. 1 m untuk volume s.d. 200 m3 secara manual
C64: TENAGA KERJA
C65: Pekerja | D65: 0.75 | E65: OH | H65: =IFERROR(I9*D65,0)
C66: Mandor | D66: 0.038 | E66: OH | H66: =IFERROR(I9*D66,0)
C68: Pemasangan 1 m3 batu kosong (anstamping) untuk pondasi gedung
C69: Uraian | D69: Koefisien | E69: Sat.
C70: TENAGA KERJA
C71: Pekerja | D71: 0.78 | E71: OH | H71: =IFERROR(I11*D71,0) | I71: =IFERROR(H65+H71+H81+H91+H101+H106+H113,0)
C72: Tukang batu | D72: 0.39 | E72: OH | H72: =IFERROR(I11*D72,0) | I72: =IFERROR(H72+H82+H92,0)
C73: Kepala tukang | D73: 0.039 | E73: OH | H73: =IFERROR(I11*D73,0) | I73: =IFERROR(D73,0)
C74: Mandor | D74: 0.013 | E74: OH | H74: =IFERROR(I11*D74,0) | I74: =IFERROR(H66+H74+H83+H93+H102+H107+H114,0)
C75: BAHAN
C76: Batu belah | D76: 1.2 | E76: m3 | H76: =IFERROR(I11*D76,0)
C77: Pasir uruk | D77: 0.432 | E77: m3 | H77: =IFERROR(I11*D77,0)
...

Sheet Foot Plate
D3: AHSP S.E. BHINA KONSTRUKSI NO. 30 TAHUN 2025
B5: 3. | C5: PEKERJAAN PONDASI TAPAK BETON/FOOT PLATE
B7: 3.1 | C7: Dimensi Utama | F7: 3.2 | G7: Volume | L7: 3.3 | M7: Result
B8: a1 | C8: Lebar Kolom 1 | D8: 0.25 | E8: m | F8: d1 | G8: Jumlah Besi D1 | I8: =IFERROR((D12+D14+D15+D8+10*D20/1000)*D25,0) | J8: m | M8: Uraian | O8: Volume | P8: Satuan | Q8: Harga Satuan (Rp) | R8: Jumlah Harga (Rp)
B9: a2 | C9: Lebar Kolom 2 | D9: 0.25 | E9: m | F9: d2 | G9: Jumlah Besi D2 | I9: =IFERROR((D12+D14+D15+D8+10*D21/1000)*D26,0) | J9: m | L9: 1 | M9: Pekerja | O9: =I58 | P9: OH | Q9: 100000 | R9: =IFERROR((Q9*O9)*L9,0)
B10: b1 | C10: Lebar Tapak 1 | D10: 0.7 | E10: m | F10: d3 | G10: Jumlah Besi D3 | I10: =IFERROR(((D12+D14+D15)/D27+1)*(D8+D9+10*D22/1000-2*D34)*2,0) | J10: m | L10: 1 | M10: Tukang | O10: =I59 | P10: OH | Q10: 145000 | R10: =IFERROR((Q10*O10)*L10,0)
B11: b2 | C11: Lebar Tapak 2 | D11: 0.7 | E11: m | F11: d4 | G11: Jumlah Besi D4 | I11: =IFERROR((D10/D27+1)*(D11+2*10*D30/1000)+(D11/D27+1)*(D10+2*10*D30/1000),0) | J11: m | L11: 1 | M11: Kepala Tukang | O11: =I60 | P11: OH | Q11: 175000 | R11: =IFERROR((Q11*O11)*L11,0)
B12: h1 | C12: Tinggi Kolom | D12: 1.5 | E12: m | F12: d5 | G12: Jumlah Besi D5 | I12: =IFERROR((D10/D27+1)*(D11+2*D14+2*D15+2*10*D31/1000)+(D11/D27+1)*(D10+2*D14+2*D15+2*10*D31/1000),0) | J12: m | L12: 1 | M12: Mandor | O12: =I61 | P12: OH | Q12: 200000 | R12: =IFERROR((Q12*O12)*L12,0)
F13: d6 | G13: Jumlah Besi D6 | I13: =IFERROR((D8+1.25*2*(D14+D15)+2*10*D32/1000)*4,0) | J13: m | O13: Jumlah Harga Tenaga Kerja = | R13: =SUM(R9:R12)
B14: h2 | C14: Kemiringan Tapak | D14: 0.1 | E14: m | G14: Jumlah Kawat Beton | I14: =IFERROR(((D12/D27+1)*(D25+D26)+(D10/D27+1)*(D11/D27+1))*(D28),0) | J14: m | M14: BAHAN
B15: h3 | C15: Tinggi Tapak | D15: 0.3 | E15: m | M15: ="Besi utama, dia: "&D20&" mm" | O15: =IFERROR(I24/12,0) | P15: batang | Q15: 196700 | R15: =IFERROR(Q15*O15,0)
B16: h4 | C16: Tinggi Lantai Kerja | D16: 0.05 | E16: m | G16: Galian Pondasi | I16: =IFERROR(D10*D11*(D12+D14+D15+D16+D17)*D18*1,0) | J16: m³ | M16: ="Besi support, dia: "&D21&" mm" | O16: =IFERROR(I25/12,0) | P16: batang | Q16: 196700 | R16: =IFERROR(Q16*O16,0)
B17: h5 | C17: Tinggi Urugan Pasir | D17: 0.1 | E17: m | G17: Urugan Pasir Pondasi | I17: =IFERROR(D10*D11*D17*D18*1,0) | J17: m³ | M17: ="Besi sengkang, dia: "&D22&" mm" | O17: =IFERROR(I26/12,0) | P17: batang | Q17: 67800 | R17: =IFERROR(Q17*O17,0)
C18: Jumlah Pondasi Tapak | D18: 5 | E18: unit | G18: Pekerjaan Pembesian | I18: =IFERROR(0.785*D35/(10^6)*(I8*D20^2+I9*D21^2+I10*D22^2+I11*D30^2+I12*D31^2+I13*D32^2+I14*D23^2)*D18*1,0) | J18: kg | M18: ="Besi alas, dia: "&D30&" mm" | O18: =IFERROR(I27/12,0) | P18: batang | Q18: 117200 | R18: =IFERROR(Q18*O18,0)
C19: Besi Kaki Kolom | G19: Pekerjaan Bekisting | I19: =IFERROR(((D10+D11)*2*D15*D18+(D8+D9)*2*D12*D18)*1,0) | J19: m² | M19: ="Besi pembentuk, dia: "&D31&" mm" | O19: =IFERROR(I28/12,0) | P19: batang | Q19: 117200 | R19: =IFERROR(Q19*O19,0)
B20: d1 | C20: Besi Utama, Ø | D20: 16 | E20: mm | G20: Pekerjaan Cor | I20: =IFERROR((D8*D9*D12+D10*D11*D15+D10*D11*D14*0.5)*D18*1,0) | J20: m³ | M20: ="Besi Kait, dia: "&D32&" mm" | O20: =IFERROR(I29/12,0) | P20: batang | Q20: 67800 | R20: =IFERROR(Q20*O20,0)
B21: d2 | C21: Besi Support, Ø | D21: 16 | E21: mm | G21: Jumlah Kawat Beton | I21: =IFERROR(0.785*D35/(10^6)*(I14*D23^2)*D18*1,0) | J21: kg | M21: ="Kawat Beton, "&D23&" mm" | O21: =I21 | P21: kg | Q21: 18800 | R21: =IFERROR(Q21*O21,0)
B22: d3 | C22: Besi Sengkang, Ø | D22: 10 | E22: mm | G22: Volume Lantai Kerja | I22: =IFERROR(D10*D11*D16*D18*1,0) | J22: m³ | M22: Kayu papan kelas III | O22: =H84 | P22: m³ | Q22: 8000000 | R22: =IFERROR(Q22*O22,0)
C23: Kawat Beton, Ø | D23: 1.2 | E23: mm | M23: Kayu balok 6/12 kelas II | O23: =H89 | P23: m³ | Q23: 11950000 | R23: =IFERROR(Q23*O23,0)
G24: Jumlah Panjang Besi d1 | I24: =IFERROR(I8*D18,0) | J24: m¹ | M24: Plywood 12 mm | O24: =H90 | P24: lembar | Q24: 167300 | R24: =IFERROR(Q24*O24,0)
C25: Jumlah Besi Utama | D25: 3 | E25: bh | G25: Jumlah Panjang Besi d2 | I25: =IFERROR(I9*D18,0) | J25: m¹ | M25: Dolken kayu φ 8-10 (4m) | O25: =H91 | P25: batang | Q25: 35000 | R25: =IFERROR(Q25*O25,0)
C26: Jumlah Besi Support | D26: 3 | E26: bh | G26: Jumlah Panjang Besi d3 | I26: =IFERROR(I10*D18,0) | J26: m¹ | M26: Minyak Bekisting | O26: =H86+H93 | P26: liter | Q26: 9500 | R26: =IFERROR(Q26*O26,0)
B27: r1 | C27: Jarak Sengkang | D27: 0.15 | E27: m | G27: Jumlah Panjang Besi d4 | I27: =IFERROR(I11*D18,0) | J27: m¹ | M27: Paku 12 cm | O27: =H92 | P27: kg | Q27: 20500 | R27: =IFERROR(Q27*O27,0)
C28: Panjang Kawat Ikat | D28: 0.35 | E28: m | G28: Jumlah Panjang Besi d5 | I28: =IFERROR(I12*D18,0) | J28: m¹ | M28: Paku 4 inch | O28: =H85 | P28: kg | Q28: 19000 | R28: =IFERROR(Q28*O28,0)
C29: Besi Tapak Pondasi | G29: Jumlah Panjang Besi d6 | I29: =IFERROR(I13*D18,0) | J29: m¹ | M29: Semen Portland (50kg) | O29: =H96 | P29: sak | Q29: 65000 | R29: =IFERROR(Q29*O29,0)
B30: d4 | C30: Besi Alas (merah), Ø | D30: 13 | E30: mm | G30: Panjang Kawat Beton | I30: =IFERROR(I14*D18,0) | J30: m¹ | M30: Pasir beton | O30: =H97 | P30: m³ | Q30: 420000 | R30: =IFERROR(Q30*O30,0)
B31: d5 | C31: Besi Pembentuk (hijau),Ø | D31: 13 | E31: mm | M31: Batu split | O31: =H98 | P31: m³ | Q31: 400000 | R31: =IFERROR(Q31*O31,0)
B32: d6 | C32: Besi Kait (kuning), Ø | D32: 10 | E32: mm | M32: Air | O32: =H99 | P32: liter | Q32: 200 | R32: =IFERROR(Q32*O32,0)
B33: r2 | C33: Jarak Tulangan | D33: 0.15 | E33: m | M33: Pasir uruk | O33: =I17 | P33: m³ | Q33: 254700 | R33: =IFERROR(Q33*O33,0)
C34: Selimut Beton | D34: 0.03 | E34: m | O34: Jumlah Harga Bahan = | R34: =SUM(R15:R33)
C35: Massa Jenis Besi, ρ | D35: 7850 | E35: kg/m3 | Q35: TOTAL | R35: =IFERROR((R13+R34)*L36,0)
L36: 1 | R36: Biaya Pekerjaan
C38: Gambar Panduan:
C55: AHSP S.E. DIRJEN BHINA KONSTRUKSI NO. 30 TAHUN 2025
C56: Uraian | D56: Koefisien | E56: Sat. | N56: Bekisting Tapak
C57: Penulangan kolom cara manual | I57: Jumlah | N57: =IFERROR((D10+D11)*2*D15*D18,0)
C58: Pekerja | D58: 0.0016 | E58: OH | H58: =IFERROR(I18*D58,0) | I58: =H58+H63+H68+H73+H78 | N58: Beksiting Kolom
C59: Tukang | D59: 0.0016 | E59: OH | H59: =IFERROR(I18*D59,0) | I59: =H59+H64+H69+H74 | N59: =IFERROR((D8+D9)*2*D12*D18,0)
C60: Kepala Tukang | D60: 0.00016 | E60: OH | H60: =IFERROR(I18*D60,0) | I60: =H60+H65+H70+H75
C61: Mandor | D61: 0.00016 | E61: OH | H61: =IFERROR(I18*D61,0) | I61: =H61+H66+H71+H76+H79
...

Sheet Sloof
D3: AHSP S.E. BHINA KONSTRUKSI NO. 30 TAHUN 2025
B5: 4. | C5: PEKERJAAN STRUKTUR SLOOF BETON
B7: 4.1 | C7: Dimensi Utama | F7: 4.2 | G7: Volume | L7: 4.3 | M7: Result
C8: Ukuran sloof beton | G8: Panjang besi 1 set sloof | M8: Uraian | O8: Volume | P8: Satuan | Q8: Harga Satuan (Rp) | R8: Jumlah Harga (Rp)
B9: P | C9: Panjang sloof | D9: 3 | E9: m | G9: Besi tulangan 1 | I9: =IFERROR((D9+(I14*2)+(I15*2))*D19,0) | J9: m | L9: 1 | M9: Pekerja | O9: =I55 | P9: OH | Q9: 100000 | R9: =IFERROR((Q9*O9)*L9,0)
B10: b | C10: Lebar Sloof | D10: 0.2 | E10: m | G10: Besi tulangan 2 | I10: =(D9+(I14*2)+(I15*2))*D20 | J10: m | L10: 1 | M10: Tukang | O10: =I56 | P10: OH | Q10: 145000 | R10: =IFERROR((Q10*O10)*L10,0)
B11: h | C11: Tinggi Sloof | D11: 0.3 | E11: m | G11: Besi sengkang/ring | I11: =IFERROR(D25*(I16+I17),0) | J11: m | L11: 1 | M11: Kepala Tukang | O11: =I57 | P11: OH | Q11: 175000 | R11: =IFERROR((Q11*O11)*L11,0)
C12: Jumlah sloof | D12: 5 | E12: unit | G12: Kawat beton | I12: =IFERROR(I31*I32,0) | J12: m | L12: 1 | M12: Mandor | O12: =I58 | P12: OH | Q12: 200000 | R12: =IFERROR((Q12*O12)*L12,0)
C13: Diameter besi tulangan | G13: Keterangan | O13: Jumlah Harga Tenaga Kerja = | R13: =SUM(R9:R12)
C14: Besi tulangan 1, Ø | D14: 10 | E14: mm | G14: Besi kait | I14: =(MAX(D14:D15))*10/1000 | J14: m | M14: BAHAN
C15: Besi tulangan 2, Ø | D15: 8 | E15: mm | G15: Besi overstek | I15: =D11 | J15: m | M15: ="Besi diameter: "&D14&" mm" | O15: =I24/12 | P15: batang | Q15: 67800 | R15: =IFERROR(Q15*O15,0)
C16: Besi sengkang, Ø | D16: 6 | E16: mm | G16: Sengkang tumpuan | I16: =ROUNDUP(D9*100/2/D21+1,0) | J16: set | M16: ="Besi diameter: "&D15&" mm" | O16: =IFERROR(I25/12,0) | P16: batang | Q16: 47500 | R16: =IFERROR(Q16*O16,0)
C17: Kawat beton, Ø | D17: 1.2 | E17: mm | G17: Sengkang lapangan | I17: =ROUNDUP(D9*100/2/D22+1,0) | J17: set | M17: ="Besi diameter: "&D16&" mm" | O17: =IFERROR(I26/12,0) | P17: batang | Q17: 36053 | R17: =IFERROR(Q17*O17,0)
C18: Jumlah besi tulangan | G18: Volume pekerjaan sloof | M18: ="Kawat beton: "&D17&" mm" | O18: =I22 | P18: kg | Q18: 18800 | R18: =IFERROR(Q18*O18,0)
C19: Jumlah besi tulangan 1 | D19: 4 | E19: bh | G19: Pekerjaan pembesian | I19: =R47 | J19: kg | M19: =C71 | O19: =H71 | P19: m³ | Q19: 8000000 | R19: =IFERROR(Q19*O19,0)
C20: Jumlah besi tulangan 2 | D20: 2 | E20: bh | G20: Pekerjaan bekisting | I20: =IFERROR((D9*D11*2)*D12,0) | J20: m² | M20: =C72 | O20: =H72 | P20: kg | Q20: 19000 | R20: =IFERROR(Q20*O20,0)
C21: Jarak sengkang tumpuan | D21: 15 | E21: cm | G21: Pekerjaan cor sloof | I21: =IFERROR((D9*D10*D11)*D12,0) | J21: m³ | M21: =C73 | O21: =H73 | P21: liter | Q21: 16800 | R21: =IFERROR(Q21*O21,0)
C22: Jarak sengkang lapangan | D22: 20 | E22: cm | G22: Jumlah kawat beton | I22: =IFERROR((R42*I27)*D27,0) | J22: kg | M22: =C83 | O22: =H83 | P22: sak | Q22: 65000 | R22: =IFERROR(Q22*O22,0)
C23: Keterangan | G23: Jumlah panjang besi sloof | M23: =C84 | O23: =H84 | P23: m³ | Q23: 420000 | R23: =IFERROR(Q23*O23,0)
B24: s | C24: Selimut beton | D24: 2.5 | E24: cm | G24: Panjang besi tulangan 1 | I24: =IFERROR(I9*D12,0) | J24: m | M24: =C85 | O24: =H85 | P24: m³ | Q24: 400000 | R24: =IFERROR(Q24*O24,0)
C25: Panjang besi sengkang | D25: =((D10+D11)*2)-(D24*8/100)+(10*D16*2/1000) | E25: m | G25: Panjang besi tulangan 2 | I25: =IFERROR(I10*D12,0) | J25: m | M25: =C86 | O25: =H86 | P25: liter | Q25: 200 | R25: =IFERROR(Q25*O25,0)
C26: Panjang kawat ikat | D26: 0.35 | E26: m | G26: Panjang besi sengkang | I26: =IFERROR(I11*D12,0) | J26: m | O26: Jumlah Harga Bahan = | R26: =SUM(R15:R25)
C27: Massa jenis besi, ρ | D27: 7850 | E27: kg/m³ | G27: Panjang kawat beton | I27: =IFERROR(I12*D12,0) | J27: m | Q27: TOTAL | R27: =IFERROR(R13+R26,0)
R28: Biaya Pekerjaan
I31: =IFERROR((D19+D20)*D26,0)
I32: =IFERROR((I16+I17)+1,0)
R41: =((D17/1000))
R42: =PI()*(R41/2)^2
Q44: =((D14/1000)) | R44: =IFERROR((Q45*I24)*D27,0)
Q45: =PI()*(Q44/2)^2 | R45: =IFERROR((Q48*I25)*D27,0)
R46: =IFERROR((Q51*I26)*D27,0)
Q47: =((D15/1000)) | R47: =SUM(R44:R46)
Q48: =PI()*(Q47/2)^2
C50: AHSP S.E. DIRJEN BHINA KONSTRUKSI NO. 30 TAHUN 2025 | Q50: =((D16/1000))
Q51: =PI()*(Q50/2)^2
C52: 1 kg Penulangan Kolom, Balok, Ring Balk dan Sloof untuk BjTP diameter <12 mm cara Manual
C53: Uraian | D53: Koefisien | E53: Sat.
C54: TENAGA KERJA
C55: Pekerja | D55: 0.0016 | E55: OH | H55: =IFERROR(I19*D55,0) | I55: =H55+H66+H78+H91
C56: Tukang besi | D56: 0.0016 | E56: OH | H56: =IFERROR(I19*D56,0) | I56: =H56+H67+H79
...

Sheet Kolom
D3: AHSP S.E. BHINA KONSTRUKSI NO. 30 TAHUN 2025
B5: 5. | C5: PEKERJAAN STRUKTUR KOLOM BETON
B7: 5.1 | C7: Dimensi Utama | F7: 5.2 | G7: Volume | L7: 5.3 | M7: Result
C8: Ukuran kolom beton | G8: Panjang besi 1 set kolom | M8: Uraian | O8: Volume | P8: Satuan | Q8: Harga Satuan (Rp) | R8: Jumlah Harga (Rp)
B9: T | C9: Tinggi kolom | D9: 3 | E9: m | G9: Besi utama | I9: =IFERROR((D9+I14+I15)*D19,0) | J9: m | L9: 1 | M9: Pekerja | O9: =I55 | P9: OH | Q9: 80000 | R9: =IFERROR((Q9*O9)*L9,0)
B10: L | C10: Lebar kolom | D10: 0.15 | E10: m | G10: Besi support | I10: =IFERROR((D9+I14+I15)*D20,0) | J10: m | L10: 1 | M10: Tukang | O10: =I56 | P10: OH | Q10: 135000 | R10: =IFERROR((Q10*O10)*L10,0)
B11: P | C11: Panjang kolom | D11: 0.25 | E11: m | G11: Besi sengkang/ring | I11: =IFERROR(D25*I16,0) | J11: m | L11: 1 | M11: Kepala Tukang | O11: =I57 | P11: OH | Q11: 150000 | R11: =IFERROR((Q11*O11)*L11,0)
C12: Jumlah kolom | D12: 5 | E12: unit | G12: Kawat beton | I12: =IFERROR((D19+D20)*(I16+1)*D26,0) | J12: m | L12: 1 | M12: Mandor | O12: =I58 | P12: OH | Q12: 175000 | R12: =IFERROR((Q12*O12)*L12,0)
C13: Diameter besi tulangan | G13: Keterangan | O13: Jumlah Harga Tenaga Kerja = | R13: =SUM(R9:R12)
B14: D1 | C14: Besi Utama, Ø | D14: 12 | E14: mm | G14: Kait atas | I14: =MAX(D14:D15)*10/1000 | J14: m | M14: BAHAN
B15: D2 | C15: Besi Support, Ø | D15: 10 | E15: mm | G15: Kait bawah | I15: =MAX(D14:D15)*10/1000 | J15: m | M15: ="Besi utama Ø, "&D14&" mm" | O15: =I24/12 | P15: batang | Q15: 67800 | R15: =IFERROR(Q15*O15,0)
C16: Besi sengkang, Ø | D16: 8 | E16: mm | G16: Jumlah sengkang | I16: =IFERROR(ROUNDUP(((D9/(D21/100))+1),0),0) | J16: set | M16: ="Besi support Ø, "&D15&" mm" | O16: =IFERROR(I25/12,0) | P16: batang | Q16: 47500 | R16: =IFERROR(Q16*O16,0)
C17: Kawat beton, Ø | D17: 1.2 | E17: mm | M17: ="Besi sengkang Ø, "&D16&" mm" | O17: =IFERROR(I26/12,0) | P17: batang | Q17: 36053 | R17: =IFERROR(Q17*O17,0)
C18: Jumlah besi tulangan | G18: Volume pekerjaan kolom | M18: ="Kawat beton Ø, "&D17&" mm" | O18: =I22 | P18: kg | Q18: 18800 | R18: =IFERROR(Q18*O18,0)
B19: D1 | C19: Jumlah besi utama | D19: 4 | E19: bh | G19: Pekerjaan pembesian | I19: =R47 | J19: kg | M19: =C71 | O19: =H71 | P19: kg | Q19: 20500 | R19: =IFERROR(Q19*O19,0)
B20: D2 | C20: Jumlah besi support | D20: 2 | E20: bh | G20: Pekerjaan bekisting | I20: =IFERROR(((D10+D11)*D9*D12)*2,0) | J20: m² | M20: =C72 | O20: =H72 | P20: liter | Q20: 9500 | R20: =IFERROR(Q20*O20,0)
C21: Jarak sengkang | D21: 15 | E21: cm | G21: Pekerjaan cor kolom | I21: =IFERROR((D10*D11*D9)*D12,0) | J21: m³ | M21: =C73 | O21: =H73 | P21: m3 | Q21: 11950000 | R21: =IFERROR(Q21*O21,0)
G22: Jumlah kawat beton | I22: =IFERROR((R42*I27)*D27,0) | J22: kg | M22: =C74 | O22: =H74 | P22: lembar | Q22: 167300 | R22: =IFERROR(Q22*O22,0)
C23: Keterangan | G23: Jumlah panjang besi kolom | M23: Dolken kayu φ 8-10 (4m) | O23: =H75 | P23: batang | Q23: 35000 | R23: =IFERROR(Q23*O23,0)
B24: S | C24: Selimut beton | D24: 2.5 | E24: cm | G24: Panjang besi utama | I24: =IFERROR(I9*D12,0) | J24: m | M24: =C85 | O24: =H85 | P24: sak | Q24: 65000 | R24: =IFERROR(Q24*O24,0)
C25: Panjang besi sengkang | D25: =((D10+D11)*2)-(D24*8/100)+(8*D16*2/1000) | E25: m | G25: Panjang besi support | I25: =IFERROR(I10*D12,0) | J25: m | M25: =C86 | O25: =H86 | P25: m³ | Q25: 400000 | R25: =IFERROR(Q25*O25,0)
C26: Panjang kawat ikat | D26: 0.35 | E26: m | G26: Panjang besi sengkang | I26: =IFERROR(I11*D12,0) | J26: m | M26: =C87 | O26: =H87 | P26: m³ | Q26: 450000 | R26: =IFERROR(Q26*O26,0)
C27: Massa jenis besi, ρ | D27: 7850 | E27: kg/m³ | G27: Panjang kawat beton | I27: =IFERROR(I12*D12,0) | J27: m | M27: =C88 | O27: =H88 | P27: liter | Q27: 200 | R27: =IFERROR(Q27*O27,0)
O28: Jumlah Harga Bahan = | R28: =SUM(R15:R27)
Q29: TOTAL | R29: =IFERROR(R13+R28,0)
R30: Biaya Pekerjaan
R41: =((D17/1000))
R42: =PI()*(R41/2)^2
Q44: =((D14/1000)) | R44: =IFERROR((Q45*I24)*D27,0)
Q45: =PI()*(Q44/2)^2 | R45: =IFERROR((Q48*I25)*D27,0)
R46: =IFERROR((Q51*I26)*D27,0)
Q47: =((D15/1000)) | R47: =SUM(R44:R46)
Q48: =PI()*(Q47/2)^2
C50: AHSP S.E. DIRJEN BHINA KONSTRUKSI NO. 30 TAHUN 2025 | Q50: =((D16/1000))
Q51: =PI()*(Q50/2)^2
C52: 1 kg Penulangan Kolom, Balok, Ring Balk dan Sloof untuk BjTP diameter <12 mm cara Manual
C53: Uraian | D53: Koefisien | E53: Sat.
C54: TENAGA KERJA
C55: Pekerja | D55: 0.0016 | E55: OH | H55: =IFERROR(I19*D55,0) | I55: =H55+H66+H80+H93
C56: Tukang besi | D56: 0.0016 | E56: OH | H56: =IFERROR(I19*D56,0) | I56: =H56+H67+H81
...

Sheet Balok
D3: AHSP S.E. BHINA KONSTRUKSI NO. 30 TAHUN 2025
B5: 6. | C5: PEKERJAAN STRUKTUR BALOK BETON
B7: 6.1 | C7: Dimensi Utama | F7: 6.2 | G7: Volume | L7: 6.3 | M7: Result
C8: Ukuran balok beton | G8: Panjang besi 1 set balok | M8: Uraian | O8: Volume | P8: Satuan | Q8: Harga Satuan (Rp) | R8: Jumlah Harga (Rp)
B9: P | C9: Panjang balok | D9: 3 | E9: m | G9: Besi tulangan 1 | I9: =IFERROR((D9+(I14*2)+(I15*2))*D19,0) | J9: m | L9: 1 | M9: Pekerja | O9: =I55 | P9: OH | Q9: 100000 | R9: =IFERROR((Q9*O9)*L9,0)
B10: b | C10: Lebar balok | D10: 0.2 | E10: m | G10: Besi tulangan 2 | I10: =(D9+(I14*2)+(I15*2))*D20 | J10: m | L10: 1 | M10: Tukang | O10: =I56 | P10: OH | Q10: 145000 | R10: =IFERROR((Q10*O10)*L10,0)
B11: h | C11: Tinggi balok | D11: 0.3 | E11: m | G11: Besi sengkang/ring | I11: =IFERROR(D25*(I16+I17),0) | J11: m | L11: 1 | M11: Kepala Tukang | O11: =I57 | P11: OH | Q11: 175000 | R11: =IFERROR((Q11*O11)*L11,0)
C12: Jumlah balok | D12: 5 | E12: unit | G12: Kawat beton | I12: =IFERROR(I31*I32,0) | J12: m | L12: 1 | M12: Mandor | O12: =I58 | P12: OH | Q12: 200000 | R12: =IFERROR((Q12*O12)*L12,0)
C13: Diameter besi tulangan | G13: Keterangan | O13: Jumlah Harga Tenaga Kerja = | R13: =SUM(R9:R12)
C14: Besi tulangan 1, Ø | D14: 10 | E14: mm | G14: Besi kait | I14: =(MAX(D14:D15))*10/1000 | J14: m | M14: BAHAN
C15: Besi tulangan 2, Ø | D15: 8 | E15: mm | G15: Besi overstek | I15: =D11 | J15: m | M15: ="Besi diameter: "&D14&" mm" | O15: =I24/12 | P15: batang | Q15: 67800 | R15: =IFERROR(Q15*O15,0)
C16: Besi sengkang, Ø | D16: 6 | E16: mm | G16: Sengkang tumpuan | I16: =ROUNDUP(D9*100/2/D21+1,0) | J16: set | M16: ="Besi diameter: "&D15&" mm" | O16: =IFERROR(I25/12,0) | P16: batang | Q16: 47500 | R16: =IFERROR(Q16*O16,0)
C17: Kawat beton, Ø | D17: 1.2 | E17: mm | G17: Sengkang lapangan | I17: =ROUNDUP(D9*100/2/D22+1,0) | J17: set | M17: ="Besi diameter: "&D16&" mm" | O17: =IFERROR(I26/12,0) | P17: batang | Q17: 36053 | R17: =IFERROR(Q17*O17,0)
C18: Jumlah besi tulangan | G18: Volume pekerjaan balok | M18: ="Kawat beton: "&D17&" mm" | O18: =I22 | P18: kg | Q18: 18800 | R18: =IFERROR(Q18*O18,0)
C19: Jumlah besi tulangan 1 | D19: 4 | E19: bh | G19: Pekerjaan pembesian | I19: =R47 | J19: kg | M19: =C71 | O19: =H71 | P19: kg | Q19: 20500 | R19: =IFERROR(Q19*O19,0)
C20: Jumlah besi tulangan 2 | D20: 2 | E20: bh | G20: Pekerjaan bekisting | I20: =IFERROR((D9*D11*2)*D12,0) | J20: m² | M20: =C72 | O20: =H72 | P20: liter | Q20: 9500 | R20: =IFERROR(Q20*O20,0)
C21: Jarak sengkang tumpuan | D21: 15 | E21: cm | G21: Pekerjaan cor balok | I21: =IFERROR((D9*D10*D11)*D12,0) | J21: m³ | M21: =C73 | O21: =H73 | P21: m3 | Q21: 11950000 | R21: =IFERROR(Q21*O21,0)
C22: Jarak sengkang lapangan | D22: 20 | E22: cm | G22: Jumlah kawat beton | I22: =IFERROR((R42*I27)*D27,0) | J22: kg | M22: =C74 | O22: =H74 | P22: lembar | Q22: 167300 | R22: =IFERROR(Q22*O22,0)
C23: Keterangan | G23: Jumlah panjang besi balok | M23: Dolken kayu φ 8-10 (4m) | O23: =H75 | P23: batang | Q23: 35000 | R23: =IFERROR(Q23*O23,0)
B24: s | C24: Selimut beton | D24: 2.5 | E24: cm | G24: Panjang besi tulangan 1 | I24: =IFERROR(I9*D12,0) | J24: m | M24: =C85 | O24: =H85 | P24: sak | Q24: 65000 | R24: =IFERROR(Q24*O24,0)
C25: Panjang besi sengkang | D25: =((D10+D11)*2)-(D24*8/100)+(10*D16*2/1000) | E25: m | G25: Panjang besi tulangan 2 | I25: =IFERROR(I10*D12,0) | J25: m | M25: =C86 | O25: =H86 | P25: m³ | Q25: 400000 | R25: =IFERROR(Q25*O25,0)
C26: Panjang kawat ikat | D26: 0.35 | E26: m | G26: Panjang besi sengkang | I26: =IFERROR(I11*D12,0) | J26: m | M26: =C87 | O26: =H87 | P26: m³ | Q26: 450000 | R26: =IFERROR(Q26*O26,0)
C27: Massa jenis besi, ρ | D27: 7850 | E27: kg/m³ | G27: Panjang kawat beton | I27: =IFERROR(I12*D12,0) | J27: m | M27: =C88 | O27: =H88 | P27: liter | Q27: 200 | R27: =IFERROR(Q27*O27,0)
O28: Jumlah Harga Bahan = | R28: =SUM(R15:R27)
Q29: TOTAL | R29: =IFERROR(R13+R28,0)
R30: Biaya Pekerjaan
I31: =IFERROR((D19+D20)*D26,0)
I32: =IFERROR((I16+I17)+1,0)
R41: =((D17/1000))
R42: =PI()*(R41/2)^2
Q44: =((D14/1000)) | R44: =IFERROR((Q45*I24)*D27,0)
Q45: =PI()*(Q44/2)^2 | R45: =IFERROR((Q48*I25)*D27,0)
R46: =IFERROR((Q51*I26)*D27,0)
Q47: =((D15/1000)) | R47: =SUM(R44:R46)
Q48: =PI()*(Q47/2)^2
C50: AHSP S.E. DIRJEN BHINA KONSTRUKSI NO. 30 TAHUN 2025 | Q50: =((D16/1000))
Q51: =PI()*(Q50/2)^2
C52: 1 kg Penulangan Kolom, Balok, Ring Balk dan Sloof untuk BjTP diameter <12 mm cara Manual
C53: Uraian | D53: Koefisien | E53: Sat.
C54: TENAGA KERJA
...

Sheet Bata Ringan
D3: AHSP S.E. BHINA KONSTRUKSI NO. 30 TAHUN 2025
B5: 7. | C5: PEKERJAAN DINDING BATA RINGAN
B7: 7.1 | C7: Dimensi Utama | K7: 7.3 | L7: Result
C8: Ukuran dinding | G8: Ukuran ampig | L8: Uraian | N8: Volume | O8: Satuan | P8: Harga Satuan (Rp) | Q8: Jumlah Harga (Rp)
B9: Pi | C9: Panjang dinding interior | D9: 36 | E9: m | F9: T2 | G9: Tinggi ampig | H9: 2.3 | I9: m | K9: 1 | L9: Pekerja | N9: =H56 | O9: OH | P9: 100000 | Q9: =IFERROR((P9*N9)*K9,0)
B10: Pe | C10: Panjang dinding eksterior | D10: 39 | E10: m | F10: a2 | G10: Lebar alas | H10: 9 | I10: m | K10: 1 | L10: Tukang | N10: =H57 | O10: OH | P10: 145000 | Q10: =IFERROR((P10*N10)*K10,0)
B11: T | C11: Tinggi dinding | D11: 3.8 | E11: m | G11: Jumlah ampig | H11: 2 | I11: set | K11: 1 | L11: Kepala Tukang | N11: =H58 | O11: OH | P11: 175000 | Q11: =IFERROR((P11*N11)*K11,0)
C12: Ukuran kusen pintu | G12: Ukuran kusen jendela | K12: 1 | L12: Mandor | N12: =H59 | O12: OH | P12: 200000 | Q12: =IFERROR((P12*N12)*K12,0)
B13: a | C13: Tinggi kusen pintu | D13: 2.1 | E13: m | F13: m | G13: Tinggi kusen jendela | H13: 1.5 | I13: m | N13: Jumlah Harga Tenaga Kerja = | Q13: =SUM(Q9:Q12)
B14: b | C14: Lebar kusen pintu | D14: 0.9 | E14: m | F14: m1 | G14: Lebar kusen jendela | H14: 0.7 | I14: m | K14: 1 | L14: Pasangan Bata Ringan Tebal 7,5 cm
C15: Jumlah pintu | D15: 6 | E15: unit | G15: Jumlah jendela | H15: 7 | I15: unit | L15: =C61 | N15: =G61 | O15: buah | P15: 8500 | Q15: =IFERROR(P15*N15,0)
C16: Bouvenlight | G16: Lubang pengurang lainnya | L16: Mortar (40 kg/sak) | N16: =IFERROR(G62/40,0) | O16: sak | P16: 74000 | Q16: =IFERROR(P16*N16,0)
B17: x | C17: Lebar Bouven | D17: 0.2 | E17: m | F17: x1 | G17: Luasan pengurang 1 | H17: 0 | I17: m²
B18: y | C18: Tinggi Bouven | D18: 0.3 | E18: m | F18: x2 | G18: Luasan pengurang 2 | H18: 0 | I18: m² | K18: 0 | L18: Pasangan Bata Ringan Tebal 10 cm
C19: Jumlah Bouven | D19: 26 | E19: unit | F19: x3 | G19: Luasan pengurang 3 | H19: 0 | I19: m² | L19: =C72 | N19: =G72 | O19: buah | P19: 11000 | Q19: =IFERROR(P19*N19,0)
L20: Mortar (40 kg/sak) | N20: =IFERROR(G73/40,0) | O20: sak | P20: 74000 | Q20: =IFERROR(P20*N20,0)
F21: 7.2 | G21: Volume
G22: Volume pasangan dinding | K22: 0 | L22: Pasangan bata Ringan Tebal 20 cm
G23: Luas pasangan dinding | H23: =IFERROR((((D9+D10)*D11)-H25)+H24,0) | I23: m² | L23: =C83 | N23: =G83 | O23: buah | P23: 20000 | Q23: =IFERROR(P23*N23,0)
G24: Luas ampig/sopi-sopi | H24: =IFERROR((0.5*H9*H10)*H11,0) | I24: m² | L24: Mortar (40 kg/sak) | N24: =IFERROR(G84/40,0) | O24: sak | P24: 74000 | Q24: =IFERROR(P24*N24,0)
G25: Luas pengurang dinding | H25: =IFERROR(D13*D14*D15+H13*H14*H15+D17*D18*D19+H17+H18+H19,0) | I25: m² | N25: Jumlah Harga Bahan = | Q25: =IFERROR(Q15+Q16+Q19+Q20+Q23+Q24,0)
P26: TOTAL | Q26: =IFERROR(Q13+Q25,0)
Q27: Biaya Pekerjaan
C51: AHSP S.E. DIRJEN BHINA KONSTRUKSI NO. 30 TAHUN 2025
C53: Pemasangan 1 m2 dinding bata ringan tebal 7,5 cm dengan mortar siap pakai
C54: Uraian | D54: Koefisien | E54: Sat.
C55: TENAGA KERJA
C56: Pekerja | D56: 0.1677 | E56: OH | G56: =IFERROR((H23*D56)*K14,0) | H56: =IFERROR(G56+G67+G78,0)
C57: Tukang batu | D57: 0.0833 | E57: OH | G57: =IFERROR((H23*D57)*K14,0) | H57: =IFERROR(G57+G68+G79,0)
C58: Kepala tukang | D58: 0.0083 | E58: OH | G58: =IFERROR((H23*D58)*K14,0) | H58: =IFERROR(G58+G69+G80,0)
C59: Mandor | D59: 0.0028 | E59: OH | G59: =IFERROR((H23*D59)*K14,0) | H59: =IFERROR(G59+G70+G81,0)
C60: BAHAN
C61: Bata ringan tebal 7,5 cm | D61: 8.75 | E61: bh | G61: =IFERROR((H23*D61)*K14,0)
C62: Mortar siap pakai | D62: 2.571 | E62: kg | G62: =IFERROR((H23*D62)*K14,0)
C64: Pemasangan 1 m2 dinding bata ringan tebal 10 cm dengan mortar siap pakai
C65: Uraian | D65: Koefisien | E65: Sat.
C66: TENAGA KERJA
C67: Pekerja | D67: 0.1677 | E67: OH | G67: =IFERROR((H23*D67)*K18,0)
C68: Tukang batu | D68: 0.0833 | E68: OH | G68: =IFERROR((H23*D68)*K18,0)
C69: Kepala tukang | D69: 0.0083 | E69: OH | G69: =IFERROR((H23*D69)*K18,0)
...

Sheet Bata Merah
D3: AHSP S.E. BHINA KONSTRUKSI NO. 30 TAHUN 2025
B5: 8. | C5: PEKERJAAN DINDING BATA MERAH
B7: 8.1 | C7: Dimensi Utama | K7: 8.3 | L7: Result
C8: Ukuran dinding | G8: Ukuran ampig | L8: Uraian | N8: Volume | O8: Satuan | P8: Harga Satuan (Rp) | Q8: Jumlah Harga (Rp)
B9: Pi | C9: Panjang dinding interior | D9: 36 | E9: m | F9: T2 | G9: Tinggi ampig | H9: 2.3 | I9: m | K9: 1 | L9: Pekerja | N9: =H56 | O9: OH | P9: 100000 | Q9: =IFERROR((P9*N9)*K9,0)
B10: Pe | C10: Panjang dinding eksterior | D10: 39 | E10: m | F10: a2 | G10: Lebar alas | H10: 9 | I10: m | K10: 1 | L10: Tukang | N10: =H57 | O10: OH | P10: 145000 | Q10: =IFERROR((P10*N10)*K10,0)
B11: T | C11: Tinggi dinding | D11: 3.8 | E11: m | G11: Jumlah ampig | H11: 2 | I11: set | K11: 1 | L11: Kepala Tukang | N11: =H58 | O11: OH | P11: 175000 | Q11: =IFERROR((P11*N11)*K11,0)
C12: Ukuran kusen pintu | G12: Ukuran kusen jendela | K12: 1 | L12: Mandor | N12: =H59 | O12: OH | P12: 200000 | Q12: =IFERROR((P12*N12)*K12,0)
B13: a | C13: Tinggi kusen pintu | D13: 2.1 | E13: m | F13: m | G13: Tinggi kusen jendela | H13: 1.5 | I13: m | N13: Jumlah Harga Tenaga Kerja = | Q13: =SUM(Q9:Q12)
B14: b | C14: Lebar kusen pintu | D14: 0.9 | E14: m | F14: m1 | G14: Lebar kusen jendela | H14: 0.7 | I14: m | K14: 1 | L14: Pasangan Bata Merah Campuran 1SP : 3PP
C15: Jumlah pintu | D15: 6 | E15: unit | G15: Jumlah jendela | H15: 7 | I15: unit | L15: =C61 | N15: =G61 | O15: buah | P15: 700 | Q15: =IFERROR(P15*N15,0)
C16: Bouvenlight | G16: Lubang pengurang lainnya | L16: Semen portland (50 kg) | N16: =G62 | O16: sak | P16: 65000 | Q16: =IFERROR(P16*N16,0)
B17: x | C17: Lebar Bouven | D17: 0.2 | E17: m | F17: x1 | G17: Luasan pengurang 1 | H17: 0 | I17: m² | L17: Pasir pasang | N17: =G63 | O17: m³ | P17: 275000 | Q17: =IFERROR(P17*N17,0)
B18: y | C18: Tinggi Bouven | D18: 0.3 | E18: m | F18: x2 | G18: Luasan pengurang 2 | H18: 0 | I18: m² | K18: 0 | L18: Pasangan Bata Merah Campuran 1SP : 4PP
C19: Jumlah Bouven | D19: 26 | E19: unit | F19: x3 | G19: Luasan pengurang 3 | H19: 0 | I19: m² | L19: =C73 | N19: =G73 | O19: buah | P19: 700 | Q19: =IFERROR(P19*N19,0)
L20: Semen portland (50 kg) | N20: =G74 | O20: sak | P20: 65000 | Q20: =IFERROR(P20*N20,0)
F21: 8.2 | G21: Volume | L21: Pasir pasang | N21: =G75 | O21: m³ | P21: 275000 | Q21: =IFERROR(P21*N21,0)
G22: Volume pasangan dinding | K22: 0 | L22: Pasangan Bata Merah Campuran 1SP : 5PP
G23: Luas pasangan dinding | H23: =IFERROR((((D9+D10)*D11)-H25)+H24,0) | I23: m² | L23: =C85 | N23: =G85 | O23: buah | P23: 700 | Q23: =IFERROR(P23*N23,0)
G24: Luas ampig/sopi-sopi | H24: =IFERROR((0.5*H9*H10)*H11,0) | I24: m² | L24: Semen portland (50 kg) | N24: =IFERROR(G86/50,0) | O24: sak | P24: 65000 | Q24: =IFERROR(P24*N24,0)
G25: Luas pengurang dinding | H25: =IFERROR(D13*D14*D15+H13*H14*H15+D17*D18*D19+H17+H18+H19,0) | I25: m² | L25: Pasir pasang | N25: =G87 | O25: m³ | P25: 275000 | Q25: =IFERROR(P25*N25,0)
N26: Jumlah Harga Bahan = | Q26: =IFERROR(Q15+Q16+Q17+Q19+Q20+Q21+Q23+Q24+Q25,0)
P27: TOTAL | Q27: =IFERROR(Q13+Q26,0)
Q28: Biaya Pekerjaan
C51: AHSP S.E. DIRJEN BHINA KONSTRUKSI NO. 30 TAHUN 2025
C53: Pemasangan 1 m2 dinding bata merah tebal 1/2 batu dengan mortar tipe S,fc’ 12,5 MPa (Setara Campuran 1SP : 3PP)
C54: Uraian | D54: Koefisien | E54: Sat.
C55: TENAGA KERJA
C56: Pekerja | D56: 0.2 | E56: OH | G56: =IFERROR((H23*D56)*K14,0) | H56: =IFERROR(G56+G68+G80,0)
C57: Tukang batu | D57: 0.1 | E57: OH | G57: =IFERROR((H23*D57)*K14,0) | H57: =IFERROR(G57+G69+G81,0)
C58: Kepala tukang | D58: 0.01 | E58: OH | G58: =IFERROR((H23*D58)*K14,0) | H58: =IFERROR(G58+G70+G82,0)
C59: Mandor | D59: 0.0033 | E59: OH | G59: =IFERROR((H23*D59)*K14,0) | H59: =IFERROR(G59+G71+G83,0)
C60: BAHAN
C61: Bata merah | D61: 71.91 | E61: bh | G61: =IFERROR((H23*D61)*K14,0)
C62: Semen portland (pc) | D62: 14.37 | E62: kg | G62: =IFERROR(((H23*D62)/50)*K14,0)
C63: Pasir pasang (quarry - lokasi pekerjaan) | D63: 0.04 | E63: m3 | G63: =IFERROR((H23*D63)*K14,0)
C65: Pemasangan 1 m2 dinding bata merah tebal 1/2 batu dengan mortar tipe N,fc’ 5,2 MPa (Setara Campuran 1SP : 4PP)
C66: Uraian | D66: Koefisien | E66: Sat.
C67: TENAGA KERJA
C68: Pekerja | D68: 0.2 | E68: OH | G68: =IFERROR((H23*D68)*K18,0)
...

Sheet Batako
D3: AHSP S.E. BHINA KONSTRUKSI NO. 30 TAHUN 2025
B5: 9. | C5: PEKERJAAN DINDING BATAKO
B7: 9.1 | C7: Dimensi Utama | K7: 9.3 | L7: Result
C8: Ukuran dinding | G8: Ukuran ampig | L8: Uraian | N8: Volume | O8: Satuan | P8: Harga Satuan (Rp) | Q8: Jumlah Harga (Rp)
B9: Pi | C9: Panjang dinding interior | D9: 36 | E9: m | F9: T2 | G9: Tinggi ampig | H9: 2.3 | I9: m | K9: 1 | L9: Pekerja | N9: =H56 | O9: OH | P9: 100000 | Q9: =IFERROR((P9*N9)*K9,0)
B10: Pe | C10: Panjang dinding eksterior | D10: 39 | E10: m | F10: a2 | G10: Lebar alas | H10: 9 | I10: m | K10: 1 | L10: Tukang | N10: =H57 | O10: OH | P10: 145000 | Q10: =IFERROR((P10*N10)*K10,0)
B11: T | C11: Tinggi dinding | D11: 3.8 | E11: m | G11: Jumlah ampig | H11: 2 | I11: set | K11: 1 | L11: Kepala Tukang | N11: =H58 | O11: OH | P11: 175000 | Q11: =IFERROR((P11*N11)*K11,0)
C12: Ukuran kusen pintu | G12: Ukuran kusen jendela | K12: 1 | L12: Mandor | N12: =H59 | O12: OH | P12: 200000 | Q12: =IFERROR((P12*N12)*K12,0)
B13: a | C13: Tinggi kusen pintu | D13: 2.1 | E13: m | F13: m | G13: Tinggi kusen jendela | H13: 1.5 | I13: m | N13: Jumlah Harga Tenaga Kerja = | Q13: =SUM(Q9:Q12)
B14: b | C14: Lebar kusen pintu | D14: 0.9 | E14: m | F14: m1 | G14: Lebar kusen jendela | H14: 0.7 | I14: m | K14: 1 | L14: Pasangan Dinding Batako Campuran 1SP : 3PP
C15: Jumlah pintu | D15: 6 | E15: unit | G15: Jumlah jendela | H15: 7 | I15: unit | L15: =C61 | N15: =G61 | O15: buah | P15: 3000 | Q15: =IFERROR(P15*N15,0)
C16: Bouvenlight | G16: Lubang pengurang lainnya | L16: Semen portland (50 kg) | N16: =G62/50 | O16: sak | P16: 65000 | Q16: =IFERROR(P16*N16,0)
B17: x | C17: Lebar Bouven | D17: 0.2 | E17: m | F17: x1 | G17: Luasan pengurang 1 | H17: 0 | I17: m² | L17: Pasir pasang | N17: =G63 | O17: m³ | P17: 275000 | Q17: =IFERROR(P17*N17,0)
B18: y | C18: Tinggi Bouven | D18: 0.3 | E18: m | F18: x2 | G18: Luasan pengurang 2 | H18: 0 | I18: m² | L18: =C64 | N18: =G64/4.74 | O18: batang | P18: 47500 | Q18: =IFERROR(P18*N18,0)
C19: Jumlah Bouven | D19: 26 | E19: unit | F19: x3 | G19: Luasan pengurang 3 | H19: 0 | I19: m²
K20: 0 | L20: Pasangan Dinding Batako Campuran 1SP : 4PP
F21: 9.2 | G21: Volume | L21: =C74 | N21: =G74 | O21: buah | P21: 3000 | Q21: =IFERROR(P21*N21,0)
G22: Volume pasangan dinding | L22: Semen portland (50 kg) | N22: =G75 | O22: sak | P22: 65000 | Q22: =IFERROR(P22*N22,0)
G23: Luas pasangan dinding | H23: =IFERROR((((D9+D10)*D11)-H25)+H24,0) | I23: m² | L23: Pasir pasang | N23: =G76 | O23: m³ | P23: 275000 | Q23: =IFERROR(P23*N23,0)
G24: Luas ampig/sopi-sopi | H24: =IFERROR((0.5*H9*H10)*H11,0) | I24: m² | L24: =C77 | N24: =G77/4.74 | O24: batang | P24: 47500 | Q24: =IFERROR(P24*N24,0)
G25: Luas pengurang dinding | H25: =IFERROR(D13*D14*D15+H13*H14*H15+D17*D18*D19+H17+H18+H19,0) | I25: m² | N25: Jumlah Harga Bahan = | Q25: =IFERROR(Q15+Q16+Q17+Q18+Q21+Q22+Q23+Q24,0)
P26: TOTAL | Q26: =IFERROR(Q13+Q25,0)
Q27: Biaya Pekerjaan
C51: AHSP S.E. DIRJEN BHINA KONSTRUKSI NO. 30 TAHUN 2025
C53: Pemasangan 1 m2 dinding batako dengan mortar tipe S,fc’ 12,5 MPa (Setara Campuran 1SP : 3PP)
C54: Uraian | D54: Koefisien | E54: Sat.
C55: TENAGA KERJA
C56: Pekerja | D56: 0.1818 | E56: OH | G56: =IFERROR((H23*D56)*K14,0) | H56: =IFERROR(G56+G69,0)
C57: Tukang batu | D57: 0.0909 | E57: OH | G57: =IFERROR((H23*D57)*K14,0) | H57: =IFERROR(G57+G70,0)
C58: Kepala tukang | D58: 0.0091 | E58: OH | G58: =IFERROR((H23*D58)*K14,0) | H58: =IFERROR(G58+G71,0)
C59: Mandor | D59: 0.003 | E59: OH | G59: =IFERROR((H23*D59)*K14,0) | H59: =IFERROR(G59+G72,0)
C60: BAHAN
C61: Batako 20x40x10 cm | D61: 14 | E61: bh | G61: =IFERROR((H23*D61)*K14,0)
C62: Semen portland (pc) | D62: 30.95 | E62: kg | G62: =IFERROR((H23*D62)*K14,0)
C63: Pasir pasang (quarry - lokasi pekerjaan) | D63: 0.0091 | E63: m3 | G63: =IFERROR((H23*D63)*K14,0)
C64: Besi angkur diameter 8 | D64: 0.28 | E64: kg | G64: =IFERROR((H23*D64)*K14,0)
C66: Pemasangan 1 m2 dinding batako dengan mortar tipe N,fc’ 5,2 MPa (Setara Campuran 1SP : 4PP)
C67: Uraian | D67: Koefisien | E67: Sat.
C68: TENAGA KERJA
C69: Pekerja | D69: 0.1667 | E69: OH | G69: =IFERROR((H23*D69)*K20,0)
...

Sheet Pintu & Jendela
D3: AHSP S.E. BHINA KONSTRUKSI NO. 30 TAHUN 2025
B5: 10. | C5: PEKERJAAN KUSEN PINTU & JENDELA KAYU
B7: 10.1 | C7: Dimensi Utama | K7: 10.3 | L7: Result
C8: Kusen pintu single | G8: Kusen pintu double | L8: Uraian | N8: Volume | O8: Satuan | P8: Harga Satuan (Rp) | Q8: Jumlah Harga (Rp)
B9: L | C9: Lebar kusen pintu | D9: 0.9 | E9: m | F9: L | G9: Lebar kusen pintu | H9: 1.2 | I9: m | K9: 1 | L9: Pekerja | N9: =H56 | O9: OH | P9: 100000 | Q9: =IFERROR((P9*N9)*K9,0)
B10: T | C10: Tinggi kusen pintu | D10: 2.05 | E10: m | F10: T | G10: Tinggi kusen pintu | H10: 2.05 | I10: m | K10: 1 | L10: Tukang | N10: =H57 | O10: OH | P10: 145000 | Q10: =IFERROR((P10*N10)*K10,0)
C11: Jumlah pintu single | D11: 1 | E11: unit | G11: Jumlah pintu double | H11: 1 | I11: unit | K11: 1 | L11: Kepala Tukang | N11: =H58 | O11: OH | P11: 175000 | Q11: =IFERROR((P11*N11)*K11,0)
C12: Kusen jendela single | G12: Kusen jendela double | K12: 1 | L12: Mandor | N12: =H59 | O12: OH | P12: 200000 | Q12: =IFERROR((P12*N12)*K12,0)
B13: L | C13: Lebar kusen jendela | D13: 0.7 | E13: m | F13: L | G13: Lebar kusen jendela | H13: 1.15 | I13: m | N13: Jumlah Harga Tenaga Kerja = | Q13: =SUM(Q9:Q12)
B14: T | C14: Tinggi kusen jendela | D14: 1.4 | E14: m | F14: T | G14: Tinggi kusen jendela | H14: 1.4 | I14: m | K14: 0 | L14: Kusen Pintu & Jendela Kayu Kelas 1, uk. 6x12 cm
C15: Jumlah jendela single | D15: 1 | E15: unit | G15: Jumlah jendela double | H15: 1 | I15: unit | L15: =C61 | N15: =G61 | O15: m³ | P15: 25000000 | Q15: =IFERROR(P15*N15,0)
C16: Daun pintu single | G16: Daun pintu double | L16: =C62 | N16: =G62 | O16: kg | P16: 25000 | Q16: =IFERROR(P16*N16,0)
B17: L | C17: Lebar daun pintu | D17: 0.8 | E17: m | F17: L | G17: Lebar daun pintu | H17: 1.1 | I17: m | L17: =C63 | N17: =G63 | O17: kg | P17: 16400 | Q17: =IFERROR(P17*N17,0)
B18: T | C18: Tinggi daun pintu | D18: 2 | E18: m | F18: T | G18: Tinggi daun pintu | H18: 2 | I18: m | K18: 1 | L18: Kusen Pintu & Jendela Kayu Kelas 1, uk. 6x15 cm
C19: Jumlah pintu single | D19: 1 | E19: unit | G19: Jumlah pintu double | H19: 1 | I19: unit | L19: =C73 | N19: =G73 | O19: m³ | P19: 25000000 | Q19: =IFERROR(P19*N19,0)
L20: =C74 | N20: =G74 | O20: kg | P20: 25000 | Q20: =IFERROR(P20*N20,0)
F21: 10.2 | G21: Volume | L21: =C75 | N21: =G75 | O21: kg | P21: 16400 | Q21: =IFERROR(P21*N21,0)
G22: Volume pekerjaan | K22: 0 | L22: Kusen Pintu & Jendela Aluminium
G23: Panjang kusen pintu | H23: =IFERROR(((((D10*2)+D9)*D11)+(H10*2)+H9)*H11,0) | I23: m¹ | L23: =C85 | N23: =G85 | O23: =E85 | P23: 130000 | Q23: =IFERROR(P23*N23,0)
G24: Panjang kusen jendela | H24: =Q38+Q39 | I24: m¹ | L24: =C86 | N24: =G86 | O24: buah | P24: 1600 | Q24: =IFERROR(P24*N24,0)
G25: Luas daun panel pintu | H25: =IFERROR((D17*D18*D19)+H17*H18*H19,) | I25: m² | L25: =C87 | N25: =G87 | O25: tube | P25: 33100 | Q25: =IFERROR(P25*N25,0)
G26: Total panjang kusen | H26: =IFERROR(H23+H24,0) | I26: m¹ | K26: 1 | L26: Daun Panel Pintu Kayu Kelas 1
L27: =C97 | N27: =G97 | O27: m³ | P27: 11950000 | Q27: =IFERROR(P27*N27,0)
L28: =C98 | N28: =G98 | O28: kg | P28: 16400 | Q28: =IFERROR(P28*N28,0)
N29: Jumlah Harga Bahan = | Q29: =IFERROR(Q15+Q16+Q17+Q19+Q20+Q21+Q23+Q24+Q25+Q27+Q28,0)
P30: TOTAL | Q30: =IFERROR(Q13+Q29,0)
Q31: Biaya Pekerjaan
Q38: =IFERROR(((H14*3)+H13+H13)*H15,0)
Q39: =IFERROR(((D14*2)+D13+D13)*D15,0)
C52: AHSP S.E. DIRJEN BHINA KONSTRUKSI NO. 30 TAHUN 2025
C53: Pembuatan dan pemasangan 1 m’ kusen pintu dan kusen jendela, kayu kelas I uk. 6x12 cm
C54: Uraian | D54: Koefisien | E54: Sat.
C55: TENAGA KERJA
C56: Pekerja | D56: 0.2857 | E56: OH | G56: =IFERROR((H26*D56)*K14,0) | H56: =IFERROR(G56+G68+G80+G92,0)
C57: Tukang kayu | D57: 0.1429 | E57: OH | G57: =IFERROR((H26*D57)*K14,0) | H57: =IFERROR(G57+G69+G81+G93,0)
C58: Kepala tukang | D58: 0.0143 | E58: OH | G58: =IFERROR((H26*D58)*K14,0) | H58: =IFERROR(G58+G70+G82+G94,0)
C59: Mandor | D59: 0.0048 | E59: OH | G59: =IFERROR((H26*D59)*K14,0) | H59: =IFERROR(G59+G71+G83+G95,0)
C60: BAHAN
C61: Kayu balok 6/12 kelas I | D61: 0.0086 | E61: m3 | G61: =IFERROR((H26*D61)*K14,0)
C62: Paku 10 cm | D62: 0.1276 | E62: kg | G62: =IFERROR((H26*D62)*K14,0)
...

Sheet Atap Baja Ringan
D3: AHSP S.E. BHINA KONSTRUKSI NO. 30 TAHUN 2025
B5: 11. | C5: PEKERJAAN ATAP PELANA BAJA RINGAN
U6: =I9+I10
B7: 11.1 | C7: Dimensi Utama | F7: 11.2 | G7: Volume | L7: 11.3 | M7: Result | U7: =D13+D9+D13
B8: L | C8: Lebar bangunan | D8: 8.2 | E8: m | F8: S | G8: Kemiringan atap | I8: =IFERROR(ATAN(D10/(0.5*D8))*180/PI(),0) | J8: ° | M8: Uraian | O8: Volume | P8: Satuan | Q8: Harga Satuan (Rp.) | R8: Jumlah Harga (Rp) | U8: =I9+I10
B9: P | C9: Panjang bangunan | D9: 12 | E9: m | F9: D | G9: Panjang sisi miring | I9: =(D8/2)/COS(RADIANS(I8)) | J9: m | L9: 1 | M9: Pekerja | O9: =I56 | P9: OH | Q9: 100000 | R9: =IFERROR((Q9*O9)*L9,0) | U9: 2
B10: V1 | C10: Tinggi kuda-kuda | D10: 2.367 | E10: m | F10: D1 | G10: Panjang miring overstek | I10: =IFERROR((D12)/COS(RADIANS(I8)),0) | J10: m | L10: 1 | M10: Tukang | O10: =I57 | P10: OH | Q10: 145000 | R10: =IFERROR((Q10*O10)*L10,0)
L11: 1 | M11: Kepala Tukang | O11: =I58 | P11: OH | Q11: 175000 | R11: =IFERROR((Q11*O11)*L11,0)
B12: OV | C12: Overstek lebar | D12: 1 | E12: m | G12: Jumlah reng | I12: =IFERROR(ROUNDUP(((I9+I10)/D15)+1,0)*2,0) | J12: unit | L12: 1 | M12: Mandor | O12: =I59 | P12: OH | Q12: 200000 | R12: =IFERROR((Q12*O12)*L12,0)
B13: OV1 | C13: Overstek panjang | D13: 1 | E13: m | G13: Jumlah H | I13: =IFERROR(O54,0) | J13: unit | O13: Jumlah Harga Tenaga Kerja = | R13: =SUM(R9:R12)
B14: H | C14: Jarak H1, H2, dst… | D14: 1 | E14: m | G14: Jarak H? | I14: =IFERROR((N54-O54)*D14,0) | J14: m | M14: BAHAN
C15: Jarak antar reng | D15: 0.3 | E15: m | G15: Jumlah H? | I15: =IF(I14>0,1,0) | J15: unit | M15: Baja Ringan C75 x 0,75 | O15: =IFERROR(Z93*I19,0) | P15: btg | Q15: 73000 | R15: =Q15*O15
C16: Jarak kuda-kuda | D16: 1.2 | E16: m | G16: Panjang Listplank | I16: =IFERROR((U6+U7+U8)*U9,0) | J16: m¹ | M16: Baut (Screw driver) | O16: =IFERROR((Z94*I19)+I62,0) | P16: bh | Q16: 200 | R16: =Q16*O16
C17: Lebar atap metal/lembar | D17: 0.64 | E17: m² | M17: Dynabolt | O17: =IFERROR(Z95*I19,0) | P17: bh | Q17: 500 | R17: =Q17*O17
G18: Total Volume Atap | I18: =IFERROR(((I9+I10)*(D9+D13+D13))*2,0) | J18: m² | M18: Reng Baja Ringan | O18: =IFERROR(I21/6,0) | P18: btg | Q18: 32000 | R18: =Q18*O18
G19: Jumlah Kuda-kuda | I19: =IFERROR(ROUNDUP(D9/D16+1,0),0) | J19: unit | M19: Atap Metal Lembaran | O19: =IFERROR((I18*D82)/D17,0) | P19: lembar | Q19: 54000 | R19: =Q19*O19
G20: Panjang Profil C75 | I20: =IFERROR(Z92*I19,0) | J20: m¹ | M20: Paku 1 Inch | O20: =IFERROR(I18*D83,0) | P20: kg | Q20: 15000 | R20: =Q20*O20
G21: Panjang Profil Reng | I21: =I12*(D9+D13+D13) | J21: m¹ | M21: Nok Genteng Metal | O21: =IFERROR((D9+D13+D13)*D84,0) | P21: bh | Q21: 25600 | R21: =Q21*O21
M22: Paku Sekrup | O22: =IFERROR((D9+D13+D13)*D85,0) | P22: kg | Q22: 30000 | R22: =Q22*O22
L23: 1 | M23: Lisplank GRC (L. 30 cm) | O23: =IFERROR(I16*D86,0) | P23: m' | Q23: 23000 | R23: =(Q23*O23)*L23
L24: 0 | M24: Lisplank GRC (L. 20 cm) | O24: =IFERROR(I16*D87,0) | P24: m' | Q24: 21000 | R24: =(Q24*O24)*L24
M25: Paku 2 Inch | O25: =IFERROR(I16*D88,0) | P25: kg | Q25: 18000 | R25: =Q25*O25
O26: Jumlah Harga Bahan = | R26: =SUM(R15:R25)
Q27: TOTAL | R27: =IFERROR(R13+R26,0)
R28: Biaya Pekerjaan
B32: Panduan Gambar:
C53: AHSP S.E. DIRJEN BHINA KONSTRUKSI NO. 30 TAHUN 2025 | N53: ANALISA VOLUME 1 SET KUDA-KUDA BAJA RINGAN
C54: Uraian | D54: Koefisien | E54: Sat. | H54: Jumlah | N54: =IFERROR((D8/D14)/2,0) | O54: =ROUNDDOWN(N54,0)
C55: Pemasangan 1 m Kaso Baja Ringan C75 | N55: Jumlah Batang H | P55: 1 | Q55: unit | U55: Analisa Panjang Dc | X55: =IFERROR(((D8/2)/(D14*2)),0) | Y55: =IFERROR(ROUNDDOWN((D8/2)/(D14*2),0),0)
C56: Pekerja | D56: 0.0476 | E56: OH | H56: =IFERROR(I20*D56,0) | I56: =H56+H61+H66+H71+H76 | N56: Jumlah Batang Da | P56: =IFERROR(R56*T56,0) | Q56: unit | R56: =ROUNDDOWN((I13+I15)/2,0) | S56: 2 | T56: 2 | U56: Dc | V56: =(((D14*2)^2)+((O77-O79)^2))^0.5 | W56: m | X56: Jumlah Dc + Overstek | Z56: =IF(X55-Y55>=0.5,Y55+0.5,IF(X55-Y55<0.5,Y55,X55)) | AA56: m | AB56: = | AC56: =(V56*Z56)+D12 | AD56: m
C57: Tukang | D57: 0.0238 | E57: OH | H57: =IFERROR(I20*D57,0) | I57: =H57+H62+H67+H72+H77 | N57: Jumlah Batang Db | P57: =IFERROR(R57*T57,0) | Q57: unit | R57: =ROUNDUP(((I13+I15)/2)-1,0) | T57: 2 | U57: Dc1 | V57: =I14/COS(RADIANS(I8)) | W57: m | Y57: Jumlah Dc1 | Z57: =IF(D8/2=Z56,0,1) | AA57: m | AB57: = | AC57: =Z57*V57 | AD57: m
C58: Kepala Tukang | D58: 0.0024 | E58: OH | H58: =IFERROR(I20*D58,0) | I58: =H58+H63+H68+H73+H78 | N58: Jumlah Batang Dc | P58: 2 | Q58: unit | Y58: Panjang Batang Dc | AC58: =SUM(AC56:AC57)*2 | AD58: m
C59: Mandor | D59: 0.0008 | E59: OH | H59: =IFERROR(I20*D59,0) | I59: =H59+H64+H69+H74+H79 | N59: Overstek | P59: 2 | Q59: unit
C60: RENG BAJA RINGAN (1M¹) | U60: Analisa Panjang Bracket Kuda-kuda
C61: Pekerja | D61: 0.0111 | E61: OH | H61: =IFERROR(I21*D61,0) | I61: Baut Reng | N61: Analisa Panjang Batang H | U61: Jumlah Dudukan | W61: 4 | X61: unit
C62: Tukang | D62: 0.0111 | E62: OH | H62: =IFERROR(I21*D62,0) | I62: =2*I19*I12 | N62: H | Q62: H | U62: Panjang Bracket | W62: 0.2 | X62: m
C63: Kepala Tukang | D63: 0.0011 | E63: OH | H63: =IFERROR(I21*D63,0) | N63: 1 | O63: =IF($I$13>=N63,$D$14,IF($I$13+$I$15>=N63,$I$14,0)) | P63: m | Q63: 10 | R63: =IF($I$13>=Q63,$D$14,IF($I$13+$I$15>=Q63,$I$14,0)) | S63: m | W63: =W62*W61 | X63: m
C64: Mandor | D64: 0.0004 | E64: OH | H64: =IFERROR(I21*D64,0) | N64: 2 | O64: =IF($I$13>=N64,$D$14,IF($I$13+$I$15>=N64,$I$14,0)) | P64: m | Q64: 11 | R64: =IF($I$13>=Q64,$D$14,IF($I$13+$I$15>=Q64,$I$14,0)) | S64: m
C65: Pemasangan 1 m2 atap metal lembaran | N65: 3 | O65: =IF($I$13>=N65,$D$14,IF($I$13+$I$15>=N65,$I$14,0)) | P65: m | Q65: 12 | R65: =IF($I$13>=Q65,$D$14,IF($I$13+$I$15>=Q65,$I$14,0)) | S65: m | U65: Analisa Panjang Overstek Sambungan
C66: Pekerja | D66: 0.1333 | E66: OH | H66: =IFERROR(I18*D66,0) | N66: 4 | O66: =IF($I$13>=N66,$D$14,IF($I$13+$I$15>=N66,$I$14,0)) | P66: m | Q66: 13 | R66: =IF($I$13>=Q66,$D$14,IF($I$13+$I$15>=Q66,$I$14,0)) | S66: m | U66: Sambungan H | W66: 1 | X66: x | Y66: 0.5 | Z66: = | AA66: =Y66*W66 | AB66: m
...

Sheet Plesteran & Acian
D3: AHSP S.E. BHINA KONSTRUKSI NO. 30 TAHUN 2025
B5: 12. | C5: PEKERJAAN PLESTERAN DINDING & ACIAN
B7: 12.1 | C7: Dimensi Utama | K7: 12.3 | L7: Result
C8: Ukuran dinding | G8: Ukuran ampig | L8: Uraian | N8: Volume | O8: Satuan | P8: Harga Satuan (Rp) | Q8: Jumlah Harga (Rp)
B9: Pi | C9: Panjang dinding interior | D9: 36 | E9: m | F9: T2 | G9: Tinggi ampig | H9: 2.3 | I9: m | K9: 1 | L9: Pekerja | N9: =H57 | O9: OH | P9: 100000 | Q9: =IFERROR((P9*N9)*K9,0)
B10: Pe | C10: Panjang dinding eksterior | D10: 39 | E10: m | F10: a2 | G10: Lebar alas | H10: 9 | I10: m | K10: 1 | L10: Tukang | N10: =H58 | O10: OH | P10: 145000 | Q10: =IFERROR((P10*N10)*K10,0)
B11: T | C11: Tinggi dinding | D11: 3.8 | E11: m | G11: Jumlah ampig | H11: 2 | I11: set | K11: 1 | L11: Kepala Tukang | N11: =H59 | O11: OH | P11: 175000 | Q11: =IFERROR((P11*N11)*K11,0)
C12: Ukuran kusen pintu | G12: Ukuran kusen jendela | K12: 1 | L12: Mandor | N12: =H60 | O12: OH | P12: 200000 | Q12: =IFERROR((P12*N12)*K12,0)
B13: a | C13: Tinggi kusen pintu | D13: 2.1 | E13: m | F13: m | G13: Tinggi kusen jendela | H13: 1.5 | I13: m | N13: Jumlah Harga Tenaga Kerja = | Q13: =SUM(Q9:Q12)
B14: b | C14: Lebar kusen pintu | D14: 0.9 | E14: m | F14: m1 | G14: Lebar kusen jendela | H14: 0.7 | I14: m | K14: 0 | L14: Pemasangan Plesteran Dinding 1SP : 3PP
C15: Jumlah pintu | D15: 6 | E15: unit | G15: Jumlah jendela | H15: 7 | I15: unit | L15: =C62 | N15: =G62/50 | O15: sak | P15: 65000 | Q15: =IFERROR(P15*N15,0)
C16: Bouvenlight | G16: Lubang pengurang lainnya | L16: =C63 | N16: =G63 | O16: m³ | P16: 275000 | Q16: =IFERROR(P16*N16,0)
B17: x | C17: Lebar Bouven | D17: 0.2 | E17: m | F17: x1 | G17: Luasan pengurang 1 | H17: 0 | I17: m²
B18: y | C18: Tinggi Bouven | D18: 0.3 | E18: m | F18: x2 | G18: Luasan pengurang 2 | H18: 0 | I18: m² | K18: 1 | L18: Pemasangan Plesteran Dinding 1SP : 4PP
C19: Jumlah Bouven | D19: 26 | E19: unit | F19: x3 | G19: Luasan pengurang 3 | H19: 0 | I19: m² | L19: =C73 | N19: =G73/50 | O19: sak | P19: 65000 | Q19: =IFERROR(P19*N19,0)
L20: =C74 | N20: =G74 | O20: m³ | P20: 275000 | Q20: =IFERROR(P20*N20,0)
F21: 12.2 | G21: Volume
G22: Volume pasangan dinding | K22: 0 | L22: Pemasangan Plesteran Dinding Semen Instan
G23: Luas pasangan dinding | H23: =IFERROR((((D9+D10)*D11)-H25)+H24,0) | I23: m² | L23: =C84 | N23: =G84/40 | O23: sak | P23: 74000 | Q23: =IFERROR(P23*N23,0)
G24: Luas ampig/sopi-sopi | H24: =IFERROR((0.5*H9*H10)*H11,0) | I24: m²
G25: Luas pengurang dinding | H25: =IFERROR(D13*D14*D15+H13*H14*H15+D17*D18*D19+H17+H18+H19,0) | I25: m² | K25: 1 | L25: Pemasangan Acian
L26: =C94 | N26: =G94/50 | O26: sak | P26: 65000 | Q26: =IFERROR(P26*N26,0)
N27: Jumlah Harga Bahan = | Q27: =IFERROR(Q15+Q16+Q19+Q20+Q23+Q26,0)
P28: TOTAL | Q28: =IFERROR(Q13+Q27,0)
Q29: Biaya Pekerjaan
C52: AHSP S.E. DIRJEN BHINA KONSTRUKSI NO. 30 TAHUN 2025
C54: Pemasangan 1 m2 plesteran 1SP : 3PP tebal 15 mm
C55: Uraian | D55: Koefisien | E55: Sat.
C56: TENAGA KERJA
C57: Pekerja | D57: 0.2 | E57: OH | G57: =IFERROR((H23*D57)*K14,0) | H57: =IFERROR(G57+G68+G79+G89,0)
C58: Tukang batu | D58: 0.1 | E58: OH | G58: =IFERROR((H23*D58)*K14,0) | H58: =IFERROR(G58+G69+G80+G90,0)
C59: Kepala tukang | D59: 0.01 | E59: OH | G59: =IFERROR((H23*D59)*K14,0) | H59: =IFERROR(G59+G70+G81+G91,0)
C60: Mandor | D60: 0.0033 | E60: OH | G60: =IFERROR((H23*D60)*K14,0) | H60: =IFERROR(G60+G71+G82+G92,0)
C61: BAHAN
C62: Semen portland | D62: 7.776 | E62: kg | G62: =IFERROR((H23*D62)*K14,0)
C63: Pasir pasang | D63: 0.023 | E63: m3 | G63: =IFERROR((H23*D63)*K14,0)
C65: Pemasangan 1 m2 plesteran 1SP : 4PP tebal 15 mm
C66: Uraian | D66: Koefisien | E66: Sat.
C67: TENAGA KERJA
C68: Pekerja | D68: 0.2 | E68: OH | G68: =IFERROR((H23*D68)*K18,0)
...

Sheet Penutup Lantai
D3: AHSP S.E. BHINA KONSTRUKSI NO. 30 TAHUN 2025
B5: 13. | C5: PEKERJAAN PEMASANGAN PENUTUP LANTAI
B7: 13.1 | C7: Dimensi Utama | K7: 13.3 | L7: Result
C8: Luasan penutup lantai | G8: Ukuran Granit | L8: Uraian | N8: Volume | O8: Satuan | P8: Harga Satuan (Rp) | Q8: Jumlah Harga (Rp)
C9: Lantai utama | D9: 36 | E9: m² | F9: P | G9: Panjang granit | H9: 60 | I9: cm | K9: 1 | L9: Pekerja | N9: =H56 | O9: OH | P9: 100000 | Q9: =IFERROR((P9*N9)*K9,0)
C10: Lantai toilet | D10: 39 | E10: m² | F10: L | G10: Lebar granit | H10: 60 | I10: cm | K10: 1 | L10: Tukang | N10: =H57 | O10: OH | P10: 145000 | Q10: =IFERROR((P10*N10)*K10,0)
C11: Lantai teras | D11: 3.8 | E11: m² | G11: LUAS GRANIT | H11: =IFERROR((H9/100)*H10/100,0) | I11: m² | K11: 1 | L11: Kepala Tukang | N11: =H58 | O11: OH | P11: 175000 | Q11: =IFERROR((P11*N11)*K11,0)
C12: Lantai lainnya | D12: 3.8 | E12: m² | G12: Ukuran Teralux Marmer | K12: 1 | L12: Mandor | N12: =H59 | O12: OH | P12: 200000 | Q12: =IFERROR((P12*N12)*K12,0)
C13: LUAS LANTAI | D13: =SUM(D9:D12) | E13: m² | F13: P | G13: Panjang marmer | H13: 60 | I13: cm | N13: Jumlah Harga Tenaga Kerja = | Q13: =SUM(Q9:Q12)
C14: Panjang pasangan plint | F14: L | G14: Lebar marmer | H14: 60 | I14: cm | K14: 1 | L14: Pemasangan Lantai Ubin Granit 1SP : 2PP
C15: Panjang plint 1 | D15: 17.1 | E15: m¹ | G15: LUAS MARMER | H15: =IFERROR((H13/100)*H14/100,0) | I15: m² | L15: =C61 | N15: =G61 | O15: buah | P15: 120000 | Q15: =IFERROR(P15*N15,0)
C16: Panjang plint 2 | D16: 11.1 | E16: m¹ | G16: Ukuran Keramik | L16: =C62 | N16: =G62/50 | O16: sak | P16: 65000 | Q16: =IFERROR(P16*N16,0)
C17: Panjang plint 3 | D17: 15.1 | E17: m¹ | F17: P | G17: Panjang keramik | H17: 30 | I17: cm | L17: =C63 | N17: =G63/40 | O17: sak | P17: 307000 | Q17: =IFERROR(P17*N17,0)
C18: Panjang lainnya | D18: 6 | E18: m¹ | F18: L | G18: Lebar keramik | H18: 30 | I18: cm | L18: Pasir pasang | N18: =G64 | O18: m³ | P18: 275000 | Q18: =IFERROR(P18*N18,0)
C19: PANJANG PLINT | D19: =SUM(D15:D18) | E19: m¹ | G19: LUAS KERAMIK | H19: =IFERROR((H17/100)*H18/100,0) | I19: m² | K19: 0 | L19: Pemasangan Lantai Teralux Marmer 1SP : 2PP
C20: Ukuran plint | L20: =C74 | N20: =G74 | O20: buah | P20: 120000 | Q20: =IFERROR(P20*N20,0)
B21: P | C21: Panjang plint | D21: 60 | E21: cm | F21: 13.2 | G21: Volume | L21: =C75 | N21: =G75/50 | O21: sak | P21: 65000 | Q21: =IFERROR(P21*N21,0)
B22: L | C22: Lebar plint | D22: 10 | E22: cm | G22: Volume pekerjaan | L22: =C76 | N22: =G76/40 | O22: sak | P22: 307000 | Q22: =IFERROR(P22*N22,0)
C23: Panjang 1 plint | D23: =IFERROR(D21/100,0) | E23: m¹ | G23: Total luas lantai | H23: =D13 | I23: m² | L23: Pasir pasang | N23: =G77 | O23: m³ | P23: 275000 | Q23: =IFERROR(P23*N23,0)
G24: Total panjang plint | H24: =D19 | I24: m¹ | K24: 0 | L24: Pemasangan Lantai Keramik 1SP : 2PP
L25: =C87 | N25: =G87 | O25: buah | P25: 44000 | Q25: =IFERROR(P25*N25,0)
L26: =C88 | N26: =G88/50 | O26: sak | P26: 65000 | Q26: =IFERROR(P26*N26,0)
L27: =C89 | N27: =G89/40 | O27: sak | P27: 307000 | Q27: =IFERROR(P27*N27,0)
L28: Pasir pasang | N28: =G90 | O28: m³ | P28: 275000 | Q28: =IFERROR(P28*N28,0)
K29: 1 | L29: Pemasangan Plint 1SP : 2PP
L30: =C100 | N30: =G100 | O30: buah | P30: 18000 | Q30: =IFERROR(P30*N30,0)
L31: =C101 | N31: =G101/50 | O31: sak | P31: 65000 | Q31: =IFERROR(P31*N31,0)
L32: =C102 | N32: =G102/40 | O32: sak | P32: 307000 | Q32: =IFERROR(P32*N32,0)
L33: Pasir pasang | N33: =G103 | O33: m³ | P33: 275000 | Q33: =IFERROR(P33*N33,0)
N34: Jumlah Harga Bahan = | Q34: =IFERROR(Q15+Q16+Q17+Q18+Q20+Q21+Q22+Q23+Q25+Q26+Q27+Q28+Q30+Q31+Q32+Q33,0)
P35: TOTAL | Q35: =IFERROR(Q13+Q34,0)
Q36: Biaya Pekerjaan
C51: AHSP S.E. DIRJEN BHINA KONSTRUKSI NO. 30 TAHUN 2025
C53: Pemasangan 1 m2 lantai ubin granit (1SP : 2PP)
C54: Uraian | D54: Koefisien | E54: Sat.
C55: TENAGA KERJA
C56: Pekerja | D56: {=IFS(H11=0.36,"0,2500",H11=0.16,"0,1538",TRUE,"SALAH")} | E56: OH | G56: =IFERROR((H23*D56)*K14,0) | H56: =IFERROR(G56+G69+G82+G95,0)
C57: Tukang batu | D57: {=IFS(H11=0.36,"0,0833",H11=0.16,"0,0769",TRUE,"SALAH")} | E57: OH | G57: =IFERROR((H23*D57)*K14,0) | H57: =IFERROR(G57+G70+G83+G96,0)
C58: Kepala tukang | D58: {=IFS(H11=0.36,"0,0083",H11=0.16,"0,0077",TRUE,"SALAH")} | E58: OH | G58: =IFERROR((H23*D58)*K14,0) | H58: =IFERROR(G58+G71+G84+G97,0)
C59: Mandor | D59: {=IFS(H11=0.36,"0,0028",H11=0.16,"0,0026",TRUE,"SALAH")} | E59: OH | G59: =IFERROR((H23*D59)*K14,0) | H59: =IFERROR(G59+G72+G85+G98,0)
...

Sheet Penutup Dinding
D3: AHSP S.E. BHINA KONSTRUKSI NO. 30 TAHUN 2025
B5: 14. | C5: PEKERJAAN PEMASANGAN PENUTUP DINDING
B7: 14.1 | C7: Dimensi Utama | K7: 14.3 | L7: Result
C8: Luasan penutup dinding | G8: Ukuran Dinding Homogeneous Tile | L8: Uraian | N8: Volume | O8: Satuan | P8: Harga Satuan (Rp) | Q8: Jumlah Harga (Rp)
C9: Luas dinding 1 | D9: 19.5 | E9: m² | F9: P | G9: Panjang homogeneous tile | H9: 60 | I9: cm | K9: 1 | L9: Pekerja | N9: =H55 | O9: OH | P9: 100000 | Q9: =IFERROR((P9*N9)*K9,0)
C10: Luas dinding 2 | D10: 15 | E10: m² | F10: L | G10: Lebar homogeneous tile | H10: 60 | I10: cm | K10: 1 | L10: Tukang | N10: =H56 | O10: OH | P10: 145000 | Q10: =IFERROR((P10*N10)*K10,0)
C11: Luas dinding 3 | D11: 17 | E11: m² | G11: LUAS HOMOGENEOUS | H11: =IFERROR((H9/100)*H10/100,0) | I11: m² | K11: 1 | L11: Kepala Tukang | N11: =H57 | O11: OH | P11: 175000 | Q11: =IFERROR((P11*N11)*K11,0)
C12: Luas dinding lainnya | D12: 10 | E12: m² | G12: Ukuran Dinding Porselen | K12: 1 | L12: Mandor | N12: =H58 | O12: OH | P12: 200000 | Q12: =IFERROR((P12*N12)*K12,0)
C13: TOTAL LUAS DINDING | D13: =SUM(D9:D12) | E13: m² | F13: P | G13: Panjang dinding porselen | H13: 20 | I13: cm | N13: Jumlah Harga Tenaga Kerja = | Q13: =SUM(Q9:Q12)
