Workbook
Name upahbahan: 'Upah Bahan'!$F$10:$H$1348

Sheet DHSP
B2: DAFTAR HARGA SATUAN PEKERJAAN (DHSP)
B3: BIDANG BINA MARGA
B4: Berdasarkan SE Direktur Jenderal Bina Konstruksi No. 47/SE/Dk/2026 | Sumber: Lampiran V - AHSP Bidang Bina Marga (PDF, 3.125 halaman)
A6: NO | B6: KODE | C6: URAIAN PEKERJAAN | D6: SATUAN | E6: HARGA SATUAN | F6: SIFAT | G6: LAMPIRAN | H6: HAL | I6: KETERANGAN
A7: 1 | B7: ='A - Umum dan Penerapan SMKK'!M2 | C7: =VLOOKUP('A - Umum dan Penerapan SMKK'!C2,'A - Umum dan Penerapan SMKK'!$C$2:$M$21,2,FALSE) | D7: Lumsum | E7: 0 | F7: Informatif | G7: A | H7: 31 | I7: tanpa analisa
A8: 2 | B8: ='A - Umum dan Penerapan SMKK'!M5 | C8: =VLOOKUP('A - Umum dan Penerapan SMKK'!C5,'A - Umum dan Penerapan SMKK'!$C$2:$M$21,2,FALSE) | D8: Provisional Sums | E8: 0 | F8: Informatif | G8: A | H8: 33 | I8: tanpa analisa
A9: 3 | B9: ='A - Umum dan Penerapan SMKK'!M8 | C9: =VLOOKUP('A - Umum dan Penerapan SMKK'!C8,'A - Umum dan Penerapan SMKK'!$C$2:$M$21,2,FALSE) | D9: Lumsum | E9: 0 | F9: Informatif | G9: A | H9: 34 | I9: tanpa analisa
A10: 4 | B10: ='A - Umum dan Penerapan SMKK'!M11 | C10: =VLOOKUP('A - Umum dan Penerapan SMKK'!C11,'A - Umum dan Penerapan SMKK'!$C$2:$M$21,2,FALSE) | D10: Meter Panjang | E10: 0 | F10: Informatif | G10: A | H10: 37 | I10: tanpa analisa
A11: 5 | B11: ='A - Umum dan Penerapan SMKK'!M14 | C11: =VLOOKUP('A - Umum dan Penerapan SMKK'!C14,'A - Umum dan Penerapan SMKK'!$C$2:$M$21,2,FALSE) | D11: Meter Panjang | E11: 0 | F11: Informatif | G11: A | H11: 38 | I11: tanpa analisa
A12: 6 | B12: ='A - Umum dan Penerapan SMKK'!M17 | C12: =VLOOKUP('A - Umum dan Penerapan SMKK'!C17,'A - Umum dan Penerapan SMKK'!$C$2:$M$21,2,FALSE) | D12: Buah | E12: 0 | F12: Informatif | G12: A | H12: 39 | I12: tanpa analisa
A13: 7 | B13: ='A - Umum dan Penerapan SMKK'!M20 | C13: =VLOOKUP('A - Umum dan Penerapan SMKK'!C20,'A - Umum dan Penerapan SMKK'!$C$2:$M$21,2,FALSE) | E13: 0 | F13: Informatif | G13: A | H13: 40 | I13: tanpa analisa
A14: 8 | B14: ='B - Drainase'!M2 | C14: =VLOOKUP('B - Drainase'!C2,'B - Drainase'!$C$2:$M$2255,2,FALSE) | D14: Meter Kubik | E14: =VLOOKUP('B - Drainase'!C2,'B - Drainase'!$C$2:$K$2,9,FALSE) | F14: Informatif | G14: B | H14: 47
A15: 9 | B15: ='B - Drainase'!M19 | C15: =VLOOKUP('B - Drainase'!C19,'B - Drainase'!$C$2:$M$2255,2,FALSE) | D15: Meter Kubik | E15: =VLOOKUP('B - Drainase'!C19,'B - Drainase'!$C$19:$K$19,9,FALSE) | F15: Informatif | G15: B | H15: 50
A16: 10 | B16: ='B - Drainase'!M44 | C16: =VLOOKUP('B - Drainase'!C44,'B - Drainase'!$C$2:$M$2255,2,FALSE) | D16: Meter Panjang | E16: =VLOOKUP('B - Drainase'!C44,'B - Drainase'!$C$44:$K$44,9,FALSE) | F16: Informatif | G16: B | H16: 53
A17: 11 | B17: ='B - Drainase'!M66 | C17: =VLOOKUP('B - Drainase'!C66,'B - Drainase'!$C$2:$M$2255,2,FALSE) | D17: Meter Panjang | E17: =VLOOKUP('B - Drainase'!C66,'B - Drainase'!$C$66:$K$66,9,FALSE) | F17: Informatif | G17: B | H17: 56
A18: 12 | B18: ='B - Drainase'!M90 | C18: =VLOOKUP('B - Drainase'!C90,'B - Drainase'!$C$2:$M$2255,2,FALSE) | D18: Meter Panjang | E18: =VLOOKUP('B - Drainase'!C90,'B - Drainase'!$C$90:$K$90,9,FALSE) | F18: Informatif | G18: B | H18: 59
A19: 13 | B19: ='B - Drainase'!M114 | C19: =VLOOKUP('B - Drainase'!C114,'B - Drainase'!$C$2:$M$2255,2,FALSE) | D19: Meter Panjang | E19: =VLOOKUP('B - Drainase'!C114,'B - Drainase'!$C$114:$K$114,9,FALSE) | F19: Informatif | G19: B | H19: 62
A20: 14 | B20: ='B - Drainase'!M141 | C20: =VLOOKUP('B - Drainase'!C141,'B - Drainase'!$C$2:$M$2255,2,FALSE) | D20: Meter Panjang | E20: =VLOOKUP('B - Drainase'!C141,'B - Drainase'!$C$141:$K$141,9,FALSE) | F20: Informatif | G20: B | H20: 65
A21: 15 | B21: ='B - Drainase'!M165 | C21: =VLOOKUP('B - Drainase'!C165,'B - Drainase'!$C$2:$M$2255,2,FALSE) | D21: Meter Panjang | E21: =VLOOKUP('B - Drainase'!C165,'B - Drainase'!$C$165:$K$165,9,FALSE) | F21: Informatif | G21: B | H21: 68
A22: 16 | B22: ='B - Drainase'!M189 | C22: =VLOOKUP('B - Drainase'!C189,'B - Drainase'!$C$2:$M$2255,2,FALSE) | D22: Meter Panjang | E22: =VLOOKUP('B - Drainase'!C189,'B - Drainase'!$C$189:$K$189,9,FALSE) | F22: Informatif | G22: B | H22: 71 | I22: cek: sumber Rp 114.977
A23: 17 | B23: ='B - Drainase'!M213 | C23: =VLOOKUP('B - Drainase'!C213,'B - Drainase'!$C$2:$M$2255,2,FALSE) | D23: Meter Panjang | E23: =VLOOKUP('B - Drainase'!C213,'B - Drainase'!$C$213:$K$213,9,FALSE) | F23: Informatif | G23: B | H23: 74 | I23: cek: sumber Rp 182.634
A24: 18 | B24: ='B - Drainase'!M237 | C24: =VLOOKUP('B - Drainase'!C237,'B - Drainase'!$C$2:$M$2255,2,FALSE) | D24: Meter Panjang | E24: =VLOOKUP('B - Drainase'!C237,'B - Drainase'!$C$237:$K$237,9,FALSE) | F24: Informatif | G24: B | H24: 77
A25: 19 | B25: ='B - Drainase'!M271 | C25: =VLOOKUP('B - Drainase'!C271,'B - Drainase'!$C$2:$M$2255,2,FALSE) | D25: Meter Panjang | E25: =VLOOKUP('B - Drainase'!C271,'B - Drainase'!$C$271:$K$271,9,FALSE) | F25: Informatif | G25: B | H25: 80
A26: 20 | B26: ='B - Drainase'!M305 | C26: =VLOOKUP('B - Drainase'!C305,'B - Drainase'!$C$2:$M$2255,2,FALSE) | D26: Meter Panjang | E26: =VLOOKUP('B - Drainase'!C305,'B - Drainase'!$C$305:$K$305,9,FALSE) | F26: Informatif | G26: B | H26: 83
A27: 21 | B27: ='B - Drainase'!M334 | C27: =VLOOKUP('B - Drainase'!C334,'B - Drainase'!$C$2:$M$2255,2,FALSE) | D27: Meter Panjang | E27: =VLOOKUP('B - Drainase'!C334,'B - Drainase'!$C$334:$K$334,9,FALSE) | F27: Informatif | G27: B | H27: 86
A28: 22 | B28: ='B - Drainase'!M368 | C28: =VLOOKUP('B - Drainase'!C368,'B - Drainase'!$C$2:$M$2255,2,FALSE) | D28: Meter Panjang | E28: =VLOOKUP('B - Drainase'!C368,'B - Drainase'!$C$368:$K$368,9,FALSE) | F28: Informatif | G28: B | H28: 89
A29: 23 | B29: ='B - Drainase'!M402 | C29: =VLOOKUP('B - Drainase'!C402,'B - Drainase'!$C$2:$M$2255,2,FALSE) | D29: Meter Panjang | E29: =VLOOKUP('B - Drainase'!C402,'B - Drainase'!$C$402:$K$402,9,FALSE) | F29: Informatif | G29: B | H29: 92
A30: 24 | B30: ='B - Drainase'!M429 | C30: =VLOOKUP('B - Drainase'!C429,'B - Drainase'!$C$2:$M$2255,2,FALSE) | D30: Meter Panjang | E30: =VLOOKUP('B - Drainase'!C429,'B - Drainase'!$C$429:$K$429,9,FALSE) | F30: Informatif | G30: B | H30: 95
A31: 25 | B31: ='B - Drainase'!M463 | C31: =VLOOKUP('B - Drainase'!C463,'B - Drainase'!$C$2:$M$2255,2,FALSE) | D31: Meter Panjang | E31: =VLOOKUP('B - Drainase'!C463,'B - Drainase'!$C$463:$K$463,9,FALSE) | F31: Informatif | G31: B | H31: 98
A32: 26 | B32: ='B - Drainase'!M497 | C32: =VLOOKUP('B - Drainase'!C497,'B - Drainase'!$C$2:$M$2255,2,FALSE) | D32: Meter Panjang | E32: =VLOOKUP('B - Drainase'!C497,'B - Drainase'!$C$497:$K$497,9,FALSE) | F32: Informatif | G32: B | H32: 101
A33: 27 | B33: ='B - Drainase'!M524 | C33: =VLOOKUP('B - Drainase'!C524,'B - Drainase'!$C$2:$M$2255,2,FALSE) | D33: Meter Panjang | E33: =VLOOKUP('B - Drainase'!C524,'B - Drainase'!$C$524:$K$524,9,FALSE) | F33: Informatif | G33: B | H33: 104
A34: 28 | B34: ='B - Drainase'!M558 | C34: =VLOOKUP('B - Drainase'!C558,'B - Drainase'!$C$2:$M$2255,2,FALSE) | D34: Meter Panjang | E34: =VLOOKUP('B - Drainase'!C558,'B - Drainase'!$C$558:$K$558,9,FALSE) | F34: Informatif | G34: B | H34: 107
A35: 29 | B35: ='B - Drainase'!M592 | C35: =VLOOKUP('B - Drainase'!C592,'B - Drainase'!$C$2:$M$2255,2,FALSE) | D35: Meter Panjang | E35: =VLOOKUP('B - Drainase'!C592,'B - Drainase'!$C$592:$K$592,9,FALSE) | F35: Informatif | G35: B | H35: 110
A36: 30 | B36: ='B - Drainase'!M619 | C36: =VLOOKUP('B - Drainase'!C619,'B - Drainase'!$C$2:$M$2255,2,FALSE) | D36: Meter Panjang | E36: =VLOOKUP('B - Drainase'!C619,'B - Drainase'!$C$619:$K$619,9,FALSE) | F36: Informatif | G36: B | H36: 113
A37: 31 | B37: ='B - Drainase'!M646 | C37: =VLOOKUP('B - Drainase'!C646,'B - Drainase'!$C$2:$M$2255,2,FALSE) | D37: Meter Panjang | E37: =VLOOKUP('B - Drainase'!C646,'B - Drainase'!$C$646:$K$646,9,FALSE) | F37: Informatif | G37: B | H37: 116
A38: 32 | B38: ='B - Drainase'!M673 | C38: =VLOOKUP('B - Drainase'!C673,'B - Drainase'!$C$2:$M$2255,2,FALSE) | D38: Ton | E38: =VLOOKUP('B - Drainase'!C673,'B - Drainase'!$C$673:$K$673,9,FALSE) | F38: Informatif | G38: B | H38: 119
A39: 33 | B39: ='B - Drainase'!M697 | C39: =VLOOKUP('B - Drainase'!C697,'B - Drainase'!$C$2:$M$2255,2,FALSE) | D39: Meter Panjang | E39: =VLOOKUP('B - Drainase'!C697,'B - Drainase'!$C$697:$K$697,9,FALSE) | F39: Informatif | G39: B | H39: 122
A40: 34 | B40: ='B - Drainase'!M723 | C40: =VLOOKUP('B - Drainase'!C723,'B - Drainase'!$C$2:$M$2255,2,FALSE) | D40: Meter Panjang | E40: =VLOOKUP('B - Drainase'!C723,'B - Drainase'!$C$723:$K$723,9,FALSE) | F40: Informatif | G40: B | H40: 125
A41: 35 | B41: ='B - Drainase'!M749 | C41: =VLOOKUP('B - Drainase'!C749,'B - Drainase'!$C$2:$M$2255,2,FALSE) | D41: Meter Panjang | E41: =VLOOKUP('B - Drainase'!C749,'B - Drainase'!$C$749:$K$749,9,FALSE) | F41: Informatif | G41: B | H41: 128
A42: 36 | B42: ='B - Drainase'!M775 | C42: =VLOOKUP('B - Drainase'!C775,'B - Drainase'!$C$2:$M$2255,2,FALSE) | D42: Meter Panjang | E42: =VLOOKUP('B - Drainase'!C775,'B - Drainase'!$C$775:$K$775,9,FALSE) | F42: Informatif | G42: B | H42: 131
...

Sheet Upah Bahan
D4: HARGA SATUAN DASAR UPAH - MATERIAL - ALAT
D5: AHSP Bidang Bina Marga 2026 | SE Direktur Jenderal Bina Konstruksi No. 47/SE/Dk/2026
D7: NO | E7: Kode | F7: UPAH - MATERIAL - ALAT | G7: SATUAN | H7: HARGA SATUAN | I7: KETERANGAN
D8: 1 | F8: 2 | G8: 3 | H8: 4 | I8: 5
D9: I. UPAH / TENAGA KERJA | F9: I. UPAH / TENAGA KERJA
D10: 1 | E10: L01 | F10: Pekerja | G10: jam | H10: 27643.54 | I10: AHSP 2026 Bina Marga
D11: 2 | E11: L01 | F11: Pekerja Biasa | G11: Jam | H11: 27643.54 | I11: AHSP 2026 Bina Marga
D12: 3 | E12: L02 | F12: Tukang | G12: jam | H12: 29049.71 | I12: AHSP 2026 Bina Marga
D13: 4 | E13: L02 | F13: Tukang Batu | G13: jam | H13: 29049.71 | I13: AHSP 2026 Bina Marga
D14: 5 | E14: L02 | F14: Tukang Las | G14: jam | H14: 29049.71 | I14: AHSP 2026 Bina Marga
D15: 6 | E15: L03 | F15: Mandor | G15: jam | H15: 33312.62 | I15: AHSP 2026 Bina Marga
D16: 7 | E16: L03 | F16: Mandor 0,00 | G16: Jam | H16: 33312.62 | I16: AHSP 2026 Bina Marga
D17: 8 | E17: L03 | F17: Mandor Sub Total Tenaga 1.314,13 | G17: Jam | H17: 33312.62 | I17: AHSP 2026 Bina Marga
D18: 9 | E18: L03 | F18: Mandor Sub Total Tenaga 1.898,18 | G18: Jam | H18: 33312.62 | I18: AHSP 2026 Bina Marga
D19: 10 | E19: L03 | F19: Mandor Sub Total Tenaga 12.657,10 | G19: Jam | H19: 33312.62 | I19: AHSP 2026 Bina Marga
D20: 11 | E20: L03 | F20: Mandor Sub Total Tenaga 3.432,26 | G20: Jam | H20: 33312.62 | I20: AHSP 2026 Bina Marga
D21: 12 | E21: L03 | F21: Mandor Sub Total Tenaga 39.216,47 | G21: Jam | H21: 33312.62 | I21: AHSP 2026 Bina Marga
... D32: 23 | E32: L10 | F32: Kepala Tukang | G32: Jam | H32: 31517.85 | I32: AHSP 2026 Bina Marga
D33: 24 | F33: Biaya Engineering | G33: titik | H33: 225000 | I33: AHSP 2026 Bina Marga
D34: 25 | F34: Mandor (L02) | G34: Jam | H34: 33312.62 | I34: AHSP 2026 Bina Marga
D35: 26 | F35: Mandor (L03) | G35: Jam | H35: 33312.62 | I35: AHSP 2026 Bina Marga
D36: 27 | F36: Mobilisasi dan Demobilisasi Tenaga | G36: Ls | H36: 1500000 | I36: AHSP 2026 Bina Marga
D37: 28 | F37: Pekerja (L01) | G37: Jam | H37: 27643.54 | I37: AHSP 2026 Bina Marga
D38: 29 | F38: Tenaga Ahli Interpreter PDLT Test | G38: OH | H38: 849194.44 | I38: AHSP 2026 Bina Marga
D39: 30 | F39: Tenaga Instalasi Inclinometer | G39: M | H39: 45000 | I39: AHSP 2026 Bina Marga
D40: 31 | F40: Tenaga Instalasi Settlement Plate | G40: Titik | H40: 450000 | I40: AHSP 2026 Bina Marga
D41: 32 | F41: Tenaga Instalasi Water Stand Pipe | G41: M' | H41: 27500 | I41: AHSP 2026 Bina Marga
D42: 33 | F42: Tenaga Pendukung | G42: OH | H42: 407194.44 | I42: AHSP 2026 Bina Marga
D43: 34 | F43: Tenaga Pengeboran Batu | G43: M' | H43: 45000 | I43: AHSP 2026 Bina Marga
D44: 35 | F44: Tenaga Pengeboran Tanah | G44: M' | H44: 45000 | I44: AHSP 2026 Bina Marga
D45: II. MATERIAL / BAHAN | F45: II. MATERIAL / BAHAN
D46: 36 | E46: A1h | F46: Cetakan Kereb | G46: buah | H46: 750000 | I46: AHSP 2026 Bina Marga
D47: 37 | E47: EI311 | F47: Galian Tanah Biasa | G47: M3 | H47: 38354.36 | I47: AHSP 2026 Bina Marga
D48: 38 | E48: EI311 | F48: Galian tanah biasa | G48: M3 | H48: 38354.36 | I48: AHSP 2026 Bina Marga
D49: 39 | E49: EI612a | F49: Lapis Perekat | G49: liter | H49: 22050.83 | I49: AHSP 2026 Bina Marga
D50: 40 | E50: EI871b | F50: tebal 240 mikron | G50: M2 | H50: 344333.01 | I50: AHSP 2026 Bina Marga
D51: 41 | E51: EI923a | F51: Pekerjaan Galian | G51: M3 | H51: 72623.2 | I51: AHSP 2026 Bina Marga
D52: 42 | E52: L02 | F52: Tukang Sub Total Tenaga 11.619,88 | G52: Jam | H52: 29049.71 | I52: AHSP 2026 Bina Marga
D53: 43 | E53: L03 | F53: Mandor Sub Total Tenaga 11.764,94 | G53: Jam | H53: 33312.62 | I53: AHSP 2026 Bina Marga
D54: 44 | E54: L03 | F54: Mandor Sub Total Tenaga 2.005,80 | G54: Jam | H54: 33312.62 | I54: AHSP 2026 Bina Marga
...

Sheet A - Umum dan Penerapan SMKK
C2: A.1 | D2: Mobilisasi | F2: Lumsum | M2: 1.2
D3: (tidak ada tabel analisa / lembar rekapitulasi kosong pada lampiran)
C5: A.2 | D5: Pembayaran Bersyarat (Provisional Sums) | F5: Provisional Sums | M5: 1.7
D6: (tidak ada tabel analisa / lembar rekapitulasi kosong pada lampiran)
N7: Catatan:
C8: A.3 | D8: Building Information Modelling (BIM) | F8: Lumsum | M8: 1.13.(1) | N8: Biaya Umum dan Keuntungan | O8: 0.1 | Q8: 0.1
D9: (tidak ada tabel analisa / lembar rekapitulasi kosong pada lampiran)
C11: A.4 | D11: Pengeboran, termasuk SPT dan Laporan | F11: Meter Panjang | M11: 1.20.(1)
D12: (tidak ada tabel analisa / lembar rekapitulasi kosong pada lampiran)
C14: A.5 | D14: Sondir termasuk Laporan | F14: Meter Panjang | M14: 1.20.(2)
D15: (tidak ada tabel analisa / lembar rekapitulasi kosong pada lampiran)
C17: A.6 | D17: DCP-CBR termasuk Laporan | F17: Buah | M17: 1.20.(3)
D18: (tidak ada tabel analisa / lembar rekapitulasi kosong pada lampiran)
C20: A.7 | D20: Sistem Manajemen Keselamatan Konstruksi (SMKK) | M20: A.7
D21: (tidak ada tabel analisa / lembar rekapitulasi kosong pada lampiran)

Sheet B - Drainase
C2: B.1 | D2: Galian untuk Selokan Drainase dan Saluran Air | F2: Meter Kubik | K2: =ROUNDDOWN(J17,0) | M2: 2.1.(1)
C3: No | D3: Uraian | E3: Kode | F3: Sat. | G3: Koefisien | H3: Harga Satuan (Rp) | J3: Jumlah Harga (Rp)
C4: A | D4: TENAGA KERJA
C5: 1 | D5: Pekerja | E5: L01 | F5: jam | G5: 0.29141564 | H5: =VLOOKUP(D5,upahbahan,3,FALSE) | J5: =G5*H5
C6: 2 | D6: Mandor | E6: L03 | F6: jam | G6: 0.048569281 | H6: =VLOOKUP(D6,upahbahan,3,FALSE) | J6: =G6*H6
C7: JUMLAH HARGA TENAGA KERJA | J7: =SUM(J5:J6) | N7: Catatan:
C8: B | D8: BAHAN | N8: Biaya Umum dan Keuntungan | O8: 0.1 | Q8: 0.1
C9: JUMLAH HARGA BAHAN | J9: 0
C10: C | D10: PERALATAN
C11: 1 | D11: Mini Excavator | E11: E10a | F11: jam | G11: 0.048569286 | H11: =VLOOKUP(D11,upahbahan,3,FALSE) | J11: =G11*H11
C12: 2 | D12: Dump Truck | E12: E08 | F12: jam | G12: 0.11373809 | H12: 433363.61 | I12: harga khusus | J12: =G12*H12
C13: 3 | D13: Alat Bantu | F13: Ls | G13: 1 | H13: =VLOOKUP(D13,upahbahan,3,FALSE) | J13: =G13*H13
C14: JUMLAH HARGA PERALATAN | J14: =SUM(J11:J13)
C15: D | D15: Jumlah (A+B+C) | J15: =J7+J9+J14
C16: E | D16: Biaya Umum dan Keuntungan 10.0% x D | H16: =$Q$8 | J16: =J15*H16
C17: F | D17: Harga Satuan Pekerjaan (D+E) | J17: =SUM(J15:J16)
C19: B.2 | D19: Pasangan Batu dengan Mortar | F19: Meter Kubik | K19: =ROUNDDOWN(J42,0) | M19: 2.2.(1)
C20: No | D20: Uraian | E20: Kode | F20: Sat. | G20: Koefisien | H20: Harga Satuan (Rp) | J20: Jumlah Harga (Rp)
C21: A | D21: TENAGA KERJA
C22: 1 | D22: Pekerja | E22: L01 | F22: jam | G22: 1.6064256 | H22: =VLOOKUP(D22,upahbahan,3,FALSE) | J22: =G22*H22
C23: 2 | D23: Tukang Batu | E23: L02 | F23: jam | G23: 0.64257027 | H23: =VLOOKUP(D23,upahbahan,3,FALSE) | J23: =G23*H23
C24: 3 | D24: Mandor | E24: L03 | F24: jam | G24: 0.080321212 | H24: =VLOOKUP(D24,upahbahan,3,FALSE) | J24: =G24*H24
C25: JUMLAH HARGA TENAGA KERJA | J25: =SUM(J22:J24)
C26: B | D26: BAHAN
C27: 1 | D27: Batu Kali | E27: M02 | F27: M3 | G27: 1.6114409 | H27: =VLOOKUP(D27,upahbahan,3,FALSE) | J27: =G27*H27
C28: 2 | D28: Semen | E28: M12 | F28: Kg | G28: 165.375 | H28: =VLOOKUP(D28,upahbahan,3,FALSE) | J28: =G28*H28
C29: 3 | D29: Pasir | E29: M01b | F29: M3 | G29: 0.62535453 | H29: =VLOOKUP(D29,upahbahan,3,FALSE) | J29: =G29*H29
C30: 4 | D30: Air | E30: M170 | F30: Ltr | G30: 105.75017 | H30: =VLOOKUP(D30,upahbahan,3,FALSE) | J30: =G30*H30
C31: 5 | D31: Pipa Pralon Dia 2 I | E31: M280 | F31: M' | G31: 0.16025642 | H31: =VLOOKUP(D31,upahbahan,3,FALSE) | J31: =G31*H31
C32: 6 | D32: Kayu | E32: M19 | F32: M3 | G32: 0.019230771 | H32: =VLOOKUP(D32,upahbahan,3,FALSE) | J32: =G32*H32
C33: 7 | D33: Paku | E33: M18 | F33: Kg | G33: 0.28205139 | H33: =VLOOKUP(D33,upahbahan,3,FALSE) | J33: =G33*H33
C34: JUMLAH HARGA BAHAN | J34: =SUM(J27:J33)
C35: C | D35: PERALATAN
C36: 1 | D36: Concrete Mixer | E36: E06 | F36: jam | G36: 0.080321246 | H36: =VLOOKUP(D36,upahbahan,3,FALSE) | J36: =G36*H36
C37: 2 | D37: Water Tank truck | E37: E23 | F37: jam | G37: 0.021234934 | H37: =VLOOKUP(D37,upahbahan,3,FALSE) | J37: =G37*H37
C38: 3 | D38: Alat Bantu | F38: Ls | G38: 1 | H38: =VLOOKUP(D38,upahbahan,3,FALSE) | J38: =G38*H38
C39: JUMLAH HARGA PERALATAN | J39: =SUM(J36:J38)
C40: D | D40: Jumlah (A+B+C) | J40: =J25+J34+J39
C41: E | D41: Biaya Umum dan Keuntungan 10.0% x D | H41: =$Q$8 | J41: =J40*H41
C42: F | D42: Harga Satuan Pekerjaan (D+E) | J42: =SUM(J40:J41)
...

Sheet C - Tanah dan Geosintetik
C2: C.1 | D2: Galian Biasa | F2: Meter Kubik | K2: =ROUNDDOWN(J17,0) | M2: 3.1.(1)
C3: No | D3: Uraian | E3: Kode | F3: Sat. | G3: Koefisien | H3: Harga Satuan (Rp) | J3: Jumlah Harga (Rp)
C4: A | D4: TENAGA KERJA
C5: 1 | D5: Pekerja | E5: L01 | F5: Jam | G5: 0.028609216 | H5: =VLOOKUP(D5,upahbahan,3,FALSE) | J5: =G5*H5
C6: 2 | D6: Mandor | E6: L03 | F6: Jam | G6: 0.014304489 | H6: =VLOOKUP(D6,upahbahan,3,FALSE) | J6: =G6*H6
C7: JUMLAH HARGA TENAGA KERJA | J7: =SUM(J5:J6) | N7: Catatan:
C8: B | D8: BAHAN | N8: Biaya Umum dan Keuntungan | O8: 0.1 | Q8: 0.1
C9: JUMLAH HARGA BAHAN | J9: 0
C10: C | D10: PERALATAN
C11: 1 | D11: Excavator | E11: E10 | F11: Jam | G11: 0.014304524 | H11: =VLOOKUP(D11,upahbahan,3,FALSE) | J11: =G11*H11
C12: 2 | D12: DUMP TRUCK TRONTON 10 TON | E12: E35 | F12: Jam | G12: 0.039322726 | H12: =VLOOKUP(D12,upahbahan,3,FALSE) | J12: =G12*H12
C13: 3 | D13: Alat Bantu | F13: Ls | G13: 1 | H13: =VLOOKUP(D13,upahbahan,3,FALSE) | J13: =G13*H13
C14: JUMLAH HARGA PERALATAN | J14: =SUM(J11:J13)
C15: D | D15: Jumlah (A+B+C) | J15: =J7+J9+J14
C16: E | D16: Biaya Umum dan Keuntungan 10.0% x D | H16: =$Q$8 | J16: =J15*H16
C17: F | D17: Harga Satuan Pekerjaan (D+E) | J17: =SUM(J15:J16)
C19: C.2 | D19: Galian Batu Lunak | F19: Meter Kubik | K19: =ROUNDDOWN(J35,0) | M19: 3.1.(2)
C20: No | D20: Uraian | E20: Kode | F20: Sat. | G20: Koefisien | H20: Harga Satuan (Rp) | J20: Jumlah Harga (Rp)
C21: A | D21: TENAGA KERJA
C22: 1 | D22: Pekerja | E22: L01 | F22: Jam | G22: 0.020296243 | H22: =VLOOKUP(D22,upahbahan,3,FALSE) | J22: =G22*H22
C23: 2 | D23: Mandor | E23: L03 | F23: Jam | G23: 0.010148106 | H23: =VLOOKUP(D23,upahbahan,3,FALSE) | J23: =G23*H23
C24: JUMLAH HARGA TENAGA KERJA | J24: =SUM(J22:J23)
C25: B | D25: BAHAN
C26: JUMLAH HARGA BAHAN | J26: 0
C27: C | D27: PERALATAN
C28: 1 | D28: Excavator | E28: E10 | F28: Jam | G28: 0.010148121 | H28: =VLOOKUP(D28,upahbahan,3,FALSE) | J28: =G28*H28
C29: 2 | D29: DUMP TRUCK TRONTON 10 TON | E29: E35 | F29: Jam | G29: 0.031102151 | H29: =VLOOKUP(D29,upahbahan,3,FALSE) | J29: =G29*H29
C30: 3 | D30: Rock Drill Breaker | E30: E37 | F30: Jam | G30: 0.051729171 | H30: =VLOOKUP(D30,upahbahan,3,FALSE) | J30: =G30*H30
C31: 4 | D31: Alat bantu | F31: Ls | G31: 1 | H31: =VLOOKUP(D31,upahbahan,3,FALSE) | J31: =G31*H31
C32: JUMLAH HARGA PERALATAN | J32: =SUM(J28:J31)
C33: D | D33: Jumlah (A+B+C) | J33: =J24+J26+J32
C34: E | D34: Biaya Umum dan Keuntungan 10.0% x D | H34: =$Q$8 | J34: =J33*H34
C35: F | D35: Harga Satuan Pekerjaan (D+E) | J35: =SUM(J33:J34)
C37: C.3 | D37: Galian Batu | F37: Meter Kubik | K37: =ROUNDDOWN(J53,0) | M37: 3.1.(3)
C38: No | D38: Uraian | E38: Kode | F38: Sat. | G38: Koefisien | H38: Harga Satuan (Rp) | J38: Jumlah Harga (Rp)
C39: A | D39: TENAGA KERJA
C40: 1 | D40: Pekerja | E40: L01 | F40: Jam | G40: 0.020296243 | H40: =VLOOKUP(D40,upahbahan,3,FALSE) | J40: =G40*H40
C41: 2 | D41: Mandor | E41: L03 | F41: Jam | G41: 0.010148106 | H41: =VLOOKUP(D41,upahbahan,3,FALSE) | J41: =G41*H41
C42: JUMLAH HARGA TENAGA KERJA | J42: =SUM(J40:J41)
C43: B | D43: BAHAN
...

Sheet D - Preventif
C2: D.1 | D2: Pengabutan (Fog Seal) dengan Aspal Emulsi yang Mengikat Lambat (CSS-1h atau SS-1h) | F2: Liter | K2: =ROUNDDOWN(J19,0) | M2: 4.1.(1)
C3: No | D3: Uraian | E3: Kode | F3: Sat. | G3: Koefisien | H3: Harga Satuan (Rp) | J3: Jumlah Harga (Rp)
C4: A | D4: TENAGA KERJA
C5: 1 | D5: Pekerja | E5: L01 | F5: Jam | G5: 0.0070736237 | H5: =VLOOKUP(D5,upahbahan,3,FALSE) | J5: =G5*H5
C6: 2 | D6: Mandor | E6: L03 | F6: Jam | G6: 0.0017683989 | H6: =VLOOKUP(D6,upahbahan,3,FALSE) | J6: =G6*H6
C7: JUMLAH HARGA TENAGA KERJA | J7: =SUM(J5:J6) | N7: Catatan:
C8: B | D8: BAHAN | N8: Biaya Umum dan Keuntungan | O8: 0.1 | Q8: 0.1
C9: 1 | D9: Aspal Emulsi CSS-1h atau SS-1h | E9: M31a | F9: ltr | G9: 1.7894733 | H9: =VLOOKUP(D9,upahbahan,3,FALSE) | J9: =G9*H9
C10: JUMLAH HARGA BAHAN | J10: =SUM(J9:J9)
C11: C | D11: PERALATAN
C12: 1 | D12: Asphalt Distributor | E12: E41 | F12: Jam | G12: 0.001768407 | H12: =VLOOKUP(D12,upahbahan,3,FALSE) | J12: =G12*H12
C13: 2 | D13: Air Compressor | E13: E05 | F13: Jam | G13: 0.0021996444 | H13: =VLOOKUP(D13,upahbahan,3,FALSE) | J13: =G13*H13
C14: 3 | D14: Power Broom | E14: E03 | F14: Jam | G14: 0.0022912802 | H14: =VLOOKUP(D14,upahbahan,3,FALSE) | J14: =G14*H14
C15: 4 | D15: Alat Bantu | F15: Ls | G15: 1 | H15: =VLOOKUP(D15,upahbahan,3,FALSE) | J15: =G15*H15
C16: JUMLAH HARGA PERALATAN | J16: =SUM(J12:J15)
C17: D | D17: Jumlah (A+B+C) | J17: =J7+J10+J16
C18: E | D18: Biaya Umum dan Keuntungan 10.0% x D | H18: =$Q$8 | J18: =J17*H18
C19: F | D19: Harga Satuan Pekerjaan (D+E) | J19: =SUM(J17:J18)
C21: D.2 | D21: Pengabutan (Fog Seal) dengan Aspal Emulsi yang Mengikat Lebih Cepat (CQS-1h atau QS-1h) Pengabutan (Fog Seal) dengan Aspal Emulsi Modifikasi | F21: Liter | K21: =ROUNDDOWN(J38,0) | M21: 4.1.(2)
C22: No | D22: Uraian | E22: Kode | F22: Sat. | G22: Koefisien | H22: Harga Satuan (Rp) | J22: Jumlah Harga (Rp)
C23: A | D23: TENAGA KERJA
C24: 1 | D24: Pekerja | E24: L01 | F24: Jam | G24: 0.0070736237 | H24: =VLOOKUP(D24,upahbahan,3,FALSE) | J24: =G24*H24
C25: 2 | D25: Mandor | E25: L03 | F25: Jam | G25: 0.0017683989 | H25: =VLOOKUP(D25,upahbahan,3,FALSE) | J25: =G25*H25
C26: JUMLAH HARGA TENAGA KERJA | J26: =SUM(J24:J25)
C27: B | D27: BAHAN
C28: 1 | D28: Aspal Emulsi (CQS-1h atau QS-1h) | E28: M31b | F28: ltr | G28: 1.7894733 | H28: =VLOOKUP(D28,upahbahan,3,FALSE) | J28: =G28*H28
C29: JUMLAH HARGA BAHAN | J29: =SUM(J28:J28)
C30: C | D30: PERALATAN
C31: 1 | D31: Asphalt Distributor | E31: E41 | F31: Jam | G31: 0.001768407 | H31: =VLOOKUP(D31,upahbahan,3,FALSE) | J31: =G31*H31
C32: 2 | D32: Air Compressor | E32: E05 | F32: Jam | G32: 0.0021996444 | H32: =VLOOKUP(D32,upahbahan,3,FALSE) | J32: =G32*H32
C33: 3 | D33: Power Broom | E33: E03 | F33: Jam | G33: 0.0022912802 | H33: =VLOOKUP(D33,upahbahan,3,FALSE) | J33: =G33*H33
C34: 4 | D34: Alat Bantu | F34: Ls | G34: 1 | H34: =VLOOKUP(D34,upahbahan,3,FALSE) | J34: =G34*H34
C35: JUMLAH HARGA PERALATAN | J35: =SUM(J31:J34)
C36: D | D36: Jumlah (A+B+C) | J36: =J26+J29+J35
C37: E | D37: Biaya Umum dan Keuntungan 10.0% x D | H37: =$Q$8 | J37: =J36*H37
C38: F | D38: Harga Satuan Pekerjaan (D+E) | J38: =SUM(J36:J37)
C40: D.3 | D40: Polymer yang Mengikat Lebih Cepat (CQS-1hP atau QS- 1hP) | F40: Liter | K40: =ROUNDDOWN(J57,0) | M40: 4.1.(3)
C41: No | D41: Uraian | E41: Kode | F41: Sat. | G41: Koefisien | H41: Harga Satuan (Rp) | J41: Jumlah Harga (Rp)
C42: A | D42: TENAGA KERJA
C43: 1 | D43: Pekerja | E43: L01 | F43: Jam | G43: 0.0070736237 | H43: =VLOOKUP(D43,upahbahan,3,FALSE) | J43: =G43*H43
...

Sheet E - Perkerasan Berbutir dan Per
C2: E.1 | D2: Lapis Fondasi Agregat Kelas A | F2: Meter Kubik | K2: =ROUNDDOWN(J20,0) | M2: 5.1.(1a)
C3: No | D3: Uraian | E3: Kode | F3: Sat. | G3: Koefisien | H3: Harga Satuan (Rp) | J3: Jumlah Harga (Rp)
C4: A | D4: TENAGA KERJA
C5: 1 | D5: Pekerja | E5: L01 | F5: jam | G5: 0.040160558 | H5: =VLOOKUP(D5,upahbahan,3,FALSE) | J5: =G5*H5
C6: 2 | D6: Mandor | E6: L03 | F6: jam | G6: 0.0057371651 | H6: =VLOOKUP(D6,upahbahan,3,FALSE) | J6: =G6*H6
C7: JUMLAH HARGA TENAGA KERJA | J7: =SUM(J5:J6) | N7: Catatan:
C8: B | D8: BAHAN | N8: Biaya Umum dan Keuntungan | O8: 0.1 | Q8: 0.1
C9: 1 | D9: Agregat A | E9: M26 | F9: M3 | G9: 1.2612651 | H9: =VLOOKUP(D9,upahbahan,3,FALSE) | J9: =G9*H9
C10: JUMLAH HARGA BAHAN | J10: =SUM(J9:J9)
C11: C | D11: PERALATAN
C12: 1 | D12: Wheel Loader | E12: E15 | F12: jam | G12: 0.0057372284 | H12: =VLOOKUP(D12,upahbahan,3,FALSE) | J12: =G12*H12
C13: 2 | D13: Dump Truck | E13: E35 | F13: jam | G13: 0.089534928 | H13: =VLOOKUP(D13,upahbahan,3,FALSE) | J13: =G13*H13
C14: 3 | D14: Motor Grader | E14: E13 | F14: jam | G14: 0.010582004 | H14: =VLOOKUP(D14,upahbahan,3,FALSE) | J14: =G14*H14
C15: 4 | D15: Vibratory Roller | E15: E19 | F15: jam | G15: 0.013848508 | H15: =VLOOKUP(D15,upahbahan,3,FALSE) | J15: =G15*H15
C16: 5 | D16: Alat Bantu | F16: Ls | G16: 1 | H16: =VLOOKUP(D16,upahbahan,3,FALSE) | J16: =G16*H16
C17: JUMLAH HARGA PERALATAN | J17: =SUM(J12:J16)
C18: D | D18: Jumlah (A+B+C) | J18: =J7+J10+J17
C19: E | D19: Biaya Umum dan Keuntungan 10.0% x D | H19: =$Q$8 | J19: =J18*H19
C20: F | D20: Harga Satuan Pekerjaan (D+E) | J20: =SUM(J18:J19)
C22: E.2 | D22: Lapis Fondasi Agregat Kelas A dengan Mesin Gilas Pemadatan Cerdas (IC) | F22: Meter Kubik | K22: =ROUNDDOWN(J40,0) | M22: 5.1.(1b)
C23: No | D23: Uraian | E23: Kode | F23: Sat. | G23: Koefisien | H23: Harga Satuan (Rp) | J23: Jumlah Harga (Rp)
C24: A | D24: TENAGA KERJA
C25: 1 | D25: Pekerja | E25: L01 | F25: jam | G25: 0.040160558 | H25: =VLOOKUP(D25,upahbahan,3,FALSE) | J25: =G25*H25
C26: 2 | D26: Mandor | E26: L03 | F26: jam | G26: 0.0057371651 | H26: =VLOOKUP(D26,upahbahan,3,FALSE) | J26: =G26*H26
C27: JUMLAH HARGA TENAGA KERJA | J27: =SUM(J25:J26)
C28: B | D28: BAHAN
C29: 1 | D29: Agregat A | E29: M26 | F29: M3 | G29: 1.2612651 | H29: =VLOOKUP(D29,upahbahan,3,FALSE) | J29: =G29*H29
C30: JUMLAH HARGA BAHAN | J30: =SUM(J29:J29)
C31: C | D31: PERALATAN
C32: 1 | D32: Wheel Loader | E32: E15 | F32: jam | G32: 0.0057372284 | H32: =VLOOKUP(D32,upahbahan,3,FALSE) | J32: =G32*H32
C33: 2 | D33: Dump Truck | E33: E35 | F33: jam | G33: 0.15227297 | H33: =VLOOKUP(D33,upahbahan,3,FALSE) | J33: =G33*H33
C34: 3 | D34: Motor Grader | E34: E13 | F34: jam | G34: 0.010582004 | H34: =VLOOKUP(D34,upahbahan,3,FALSE) | J34: =G34*H34
C35: 4 | D35: Vibratory Roller with IC | E35: E19c | F35: jam | G35: 0.013848488 | H35: =VLOOKUP(D35,upahbahan,3,FALSE) | J35: =G35*H35
C36: 5 | D36: Alat Bantu | F36: Ls | G36: 1 | H36: =VLOOKUP(D36,upahbahan,3,FALSE) | J36: =G36*H36
C37: JUMLAH HARGA PERALATAN | J37: =SUM(J32:J36)
C38: D | D38: Jumlah (A+B+C) | J38: =J27+J30+J37
C39: E | D39: Biaya Umum dan Keuntungan 10.0% x D | H39: =$Q$8 | J39: =J38*H39
C40: F | D40: Harga Satuan Pekerjaan (D+E) | J40: =SUM(J38:J39)
C42: E.3 | D42: Lapis Fondasi Agregat Kelas B | F42: Meter Kubik | K42: =ROUNDDOWN(J60,0) | M42: 5.1.(2a)
C43: No | D43: Uraian | E43: Kode | F43: Sat. | G43: Koefisien | H43: Harga Satuan (Rp) | J43: Jumlah Harga (Rp)
...

Sheet F - Perkerasan Aspal
C2: F.1 | D2: Lapis Resap Pengikat - Aspal Cair/Emulsi | F2: Liter | K2: =ROUNDDOWN(J17,0) | M2: 6.1.(1)
C3: No | D3: Uraian | E3: Kode | F3: Sat. | G3: Koefisien | H3: Harga Satuan (Rp) | J3: Jumlah Harga (Rp)
C4: A | D4: TENAGA KERJA
C5: 1 | D5: Pekerja | E5: L01 | F5: Jam | G5: 0.0070736237 | H5: =VLOOKUP(D5,upahbahan,3,FALSE) | J5: =G5*H5
C6: 2 | D6: Mandor | E6: L03 | F6: Jam | G6: 0.0017683989 | H6: =VLOOKUP(D6,upahbahan,3,FALSE) | J6: =G6*H6
C7: JUMLAH HARGA TENAGA KERJA | J7: =SUM(J5:J6) | N7: Catatan:
C8: B | D8: BAHAN | N8: Biaya Umum dan Keuntungan | O8: 0.1 | Q8: 0.1
C9: 1 | D9: Aspal Emulsi CSS-1 (M31a) atau SS-1 | F9: Liter | G9: 1.7894733 | H9: =VLOOKUP(D9,upahbahan,3,FALSE) | J9: =G9*H9
C10: JUMLAH HARGA BAHAN | J10: =SUM(J9:J9)
C11: C | D11: PERALATAN
C12: 1 | D12: Asp. Distributor | E12: E41 | F12: Jam | G12: 0.001768407 | H12: =VLOOKUP(D12,upahbahan,3,FALSE) | J12: =G12*H12
C13: 2 | D13: Compressor | E13: E05 | F13: Jam | G13: 0.0013671772 | H13: =VLOOKUP(D13,upahbahan,3,FALSE) | J13: =G13*H13
C14: JUMLAH HARGA PERALATAN | J14: =SUM(J12:J13)
C15: D | D15: Jumlah (A+B+C) | J15: =J7+J10+J14
C16: E | D16: Biaya Umum dan Keuntungan 10.0% x D | H16: =$Q$8 | J16: =J15*H16
C17: F | D17: Harga Satuan Pekerjaan (D+E) | J17: =SUM(J15:J16)
C19: F.2 | D19: Lapis Perekat - Aspal Cair/Emulsi | F19: Liter | K19: =ROUNDDOWN(J35,0) | M19: 6.1.(2a)
C20: No | D20: Uraian | E20: Kode | F20: Sat. | G20: Koefisien | H20: Harga Satuan (Rp) | J20: Jumlah Harga (Rp)
C21: A | D21: TENAGA KERJA
C22: 1 | D22: Pekerja | E22: L01 | F22: Jam | G22: 0.0070736237 | H22: =VLOOKUP(D22,upahbahan,3,FALSE) | J22: =G22*H22
C23: 2 | D23: Mandor | E23: L03 | F23: Jam | G23: 0.0017683989 | H23: =VLOOKUP(D23,upahbahan,3,FALSE) | J23: =G23*H23
C24: JUMLAH HARGA TENAGA KERJA | J24: =SUM(J22:J23)
C25: B | D25: BAHAN
C26: 1 | D26: Aspal Emulsi CRS-1 (M31b) atau RS-1 | F26: Liter | G26: 1.7 | H26: =VLOOKUP(D26,upahbahan,3,FALSE) | J26: =G26*H26
C27: JUMLAH HARGA BAHAN | J27: =SUM(J26:J26)
C28: C | D28: PERALATAN
C29: 1 | D29: Asp. Distributor | E29: E41 | F29: Jam | G29: 0.001768407 | H29: =VLOOKUP(D29,upahbahan,3,FALSE) | J29: =G29*H29
C30: 2 | D30: Compressor | E30: E05 | F30: Jam | G30: 0.0019471889 | H30: =VLOOKUP(D30,upahbahan,3,FALSE) | J30: =G30*H30
C31: 3 | D31: Power Broom | E31: E03 | F31: Jam | G31: 0.002028343 | H31: =VLOOKUP(D31,upahbahan,3,FALSE) | J31: =G31*H31
C32: JUMLAH HARGA PERALATAN | J32: =SUM(J29:J31)
C33: D | D33: Jumlah (A+B+C) | J33: =J24+J27+J32
C34: E | D34: Biaya Umum dan Keuntungan 10.0% x D | H34: =$Q$8 | J34: =J33*H34
C35: F | D35: Harga Satuan Pekerjaan (D+E) | J35: =SUM(J33:J34)
C37: F.3 | D37: Lapis Perekat - Aspal Emulsi Modifikasi Polimer | F37: Liter | K37: =ROUNDDOWN(J53,0) | M37: 6.1.(2b)
C38: No | D38: Uraian | E38: Kode | F38: Sat. | G38: Koefisien | H38: Harga Satuan (Rp) | J38: Jumlah Harga (Rp)
C39: A | D39: TENAGA KERJA
C40: 1 | D40: Pekerja | E40: L01 | F40: Jam | G40: 0.0070736237 | H40: =VLOOKUP(D40,upahbahan,3,FALSE) | J40: =G40*H40
C41: 2 | D41: Mandor | E41: L03 | F41: Jam | G41: 0.0017683989 | H41: =VLOOKUP(D41,upahbahan,3,FALSE) | J41: =G41*H41
C42: JUMLAH HARGA TENAGA KERJA | J42: =SUM(J40:J41)
C43: B | D43: BAHAN
...

Sheet G - Struktur
C2: G.1 | D2: Beton struktur, fc’50 MPa | F2: Meter Kubik | K2: =ROUNDDOWN(J31,0) | M2: 7.1.(1a2)
C3: No | D3: Uraian | E3: Kode | F3: Sat. | G3: Koefisien | H3: Harga Satuan (Rp) | J3: Jumlah Harga (Rp)
C4: A | D4: TENAGA KERJA
C5: 1 | D5: Pekerja | E5: L01 | F5: jam | G5: 0.96385557 | H5: =VLOOKUP(D5,upahbahan,3,FALSE) | J5: =G5*H5
C6: 2 | D6: Tukang | E6: L02 | F6: jam | G6: 0.53012027 | H6: =VLOOKUP(D6,upahbahan,3,FALSE) | J6: =G6*H6
C7: 3 | D7: Mandor | E7: L03 | F7: jam | G7: 0.096385694 | H7: =VLOOKUP(D7,upahbahan,3,FALSE) | J7: =G7*H7 | N7: Catatan:
C8: JUMLAH HARGA TENAGA KERJA | J8: =SUM(J5:J7) | N8: Biaya Umum dan Keuntungan | O8: 0.1 | Q8: 0.1
C9: B | D9: BAHAN
C10: 1 | D10: Semen (PC) | E10: M12 | F10: Kg | G10: 386.35926 | H10: =VLOOKUP(D10,upahbahan,3,FALSE) | J10: =G10*H10
C11: 2 | D11: Agregat Halus | E11: M01a | F11: M3 | G11: 0.54315788 | H11: =VLOOKUP(D11,upahbahan,3,FALSE) | J11: =G11*H11
C12: 3 | D12: Agregat Kasar | E12: M03 | F12: M3 | G12: 0.92009844 | H12: =VLOOKUP(D12,upahbahan,3,FALSE) | J12: =G12*H12
C13: 4 | D13: Multipleks Phenolic 12 mm | E13: M73a | F13: Lbr | G13: 0.4451169 | H13: =VLOOKUP(D13,upahbahan,3,FALSE) | J13: =G13*H13
C14: 5 | D14: Kayu Kaso | E14: M19 | F14: M3 | G14: 0.014 | H14: =VLOOKUP(D14,upahbahan,3,FALSE) | J14: =G14*H14
C15: 6 | D15: Paku | E15: M18 | F15: Kg | G15: 1.7955 | H15: =VLOOKUP(D15,upahbahan,3,FALSE) | J15: =G15*H15
C16: 7 | D16: Air | E16: M170 | F16: Ltr | G16: 183.89761 | H16: =VLOOKUP(D16,upahbahan,3,FALSE) | J16: =G16*H16
C17: 8 | D17: Super Plastizier | E17: M182 | F17: Kg | G17: 7.714 | H17: =VLOOKUP(D17,upahbahan,3,FALSE) | J17: =G17*H17
C18: 9 | D18: Fly Ash | E18: M05 | F18: Kg | G18: 128.905 | H18: =VLOOKUP(D18,upahbahan,3,FALSE) | J18: =G18*H18
C19: JUMLAH HARGA BAHAN | J19: =SUM(J10:J18)
C20: C | D20: PERALATAN
C21: 1 | D21: Wheel Loader | E21: E15 | F21: jam | G21: 0.0070871685 | H21: =VLOOKUP(D21,upahbahan,3,FALSE) | J21: =G21*H21
C22: 2 | D22: Concrete Batching Plant | E22: E80 | F22: jam | G22: 0.048192768 | H22: 717241.22 | I22: harga khusus | J22: =G22*H22
C23: 3 | D23: Truck Mixer | E23: E49 | F23: jam | G23: 0.26181229 | H23: 847088.38 | I23: harga khusus | J23: =G23*H23
C24: 4 | D24: Concrete Pump | E24: E28 | F24: jam | G24: 0.0050200717 | H24: 571804.58 | I24: harga khusus | J24: =G24*H24
C25: 5 | D25: Concrete Vibrator | E25: E20 | F25: jam | G25: 0.28915657 | H25: =VLOOKUP(D25,upahbahan,3,FALSE) | J25: =G25*H25
C26: 6 | D26: Water Tank Truck | E26: E23 | F26: jam | G26: 0.036927254 | H26: =VLOOKUP(D26,upahbahan,3,FALSE) | J26: =G26*H26
C27: 7 | D27: Alat Bantu | F27: Ls | G27: 1 | H27: =VLOOKUP(D27,upahbahan,3,FALSE) | J27: =G27*H27
C28: JUMLAH HARGA PERALATAN | J28: =SUM(J21:J27)
C29: D | D29: Jumlah (A+B+C) | J29: =J8+J19+J28
C30: E | D30: Biaya Umum dan Keuntungan 10.0% x D | H30: =$Q$8 | J30: =J29*H30
C31: F | D31: Harga Satuan Pekerjaan (D+E) | J31: =SUM(J29:J30)
C33: G.2 | D33: Beton struktur massa, fc’50 MPa | F33: Meter Kubik | K33: =ROUNDDOWN(J63,0) | M33: 7.1.(1b)
C34: No | D34: Uraian | E34: Kode | F34: Sat. | G34: Koefisien | H34: Harga Satuan (Rp) | J34: Jumlah Harga (Rp)
C35: A | D35: TENAGA KERJA
C36: 1 | D36: Pekerja | E36: L01 | F36: jam | G36: 0.96385557 | H36: =VLOOKUP(D36,upahbahan,3,FALSE) | J36: =G36*H36
C37: 2 | D37: Tukang | E37: L02 | F37: jam | G37: 0.53012027 | H37: =VLOOKUP(D37,upahbahan,3,FALSE) | J37: =G37*H37
C38: 3 | D38: Mandor | E38: L03 | F38: jam | G38: 0.096385694 | H38: =VLOOKUP(D38,upahbahan,3,FALSE) | J38: =G38*H38
C39: JUMLAH HARGA TENAGA KERJA | J39: =SUM(J36:J38)
C40: B | D40: BAHAN
C41: 1 | D41: Semen (PC) | E41: M12 | F41: Kg | G41: 335.965 | H41: =VLOOKUP(D41,upahbahan,3,FALSE) | J41: =G41*H41
C42: 2 | D42: Agregat Halus | E42: M01a | F42: M3 | G42: 0.438891 | H42: =VLOOKUP(D42,upahbahan,3,FALSE) | J42: =G42*H42
...

Sheet H - Rehabilitasi Jembatan
C2: H.1 | D2: Cairan Perekat (Epoksi Resin) | F2: Kilogram | K2: =ROUNDDOWN(J19,0) | M2: 8.1.(1)
C3: No | D3: Uraian | E3: Kode | F3: Sat. | G3: Koefisien | H3: Harga Satuan (Rp) | J3: Jumlah Harga (Rp)
C4: A | D4: TENAGA KERJA
C5: 1 | D5: Pekerja | E5: L01 | F5: jam | G5: 3.012048 | H5: =VLOOKUP(D5,upahbahan,3,FALSE) | J5: =G5*H5
C6: 2 | D6: Mandor | E6: L03 | F6: jam | G6: 0.60240984 | H6: =VLOOKUP(D6,upahbahan,3,FALSE) | J6: =G6*H6
C7: JUMLAH HARGA TENAGA KERJA | J7: =SUM(J5:J6) | N7: Catatan:
C8: B | D8: BAHAN | N8: Biaya Umum dan Keuntungan | O8: 0.1 | Q8: 0.1
C9: 1 | D9: Epoxy resin | E9: M125 | F9: Kg | G9: 1.02 | H9: =VLOOKUP(D9,upahbahan,3,FALSE) | J9: =G9*H9
C10: JUMLAH HARGA BAHAN | J10: =SUM(J9:J9)
C11: C | D11: PERALATAN
C12: 1 | D12: Pompa untuk Epoxy | E12: E68 | F12: jam | G12: 0.60240954 | H12: =VLOOKUP(D12,upahbahan,3,FALSE) | J12: =G12*H12
C13: 2 | D13: Mini Generator Set 2000 Watt | E13: E98g | F13: jam | G13: 0.60240963 | H13: =VLOOKUP(D13,upahbahan,3,FALSE) | J13: =G13*H13
C14: 3 | D14: Hand Mixer | E14: E70 | F14: jam | G14: 0.033467243 | H14: =VLOOKUP(D14,upahbahan,3,FALSE) | J14: =G14*H14
C15: 4 | D15: Alat Bantu | F15: Ls | G15: 1 | H15: =VLOOKUP(D15,upahbahan,3,FALSE) | J15: =G15*H15
C16: JUMLAH HARGA PERALATAN | J16: =SUM(J12:J15)
C17: D | D17: Jumlah (A+B+C) | J17: =J7+J10+J16
C18: E | D18: Biaya Umum dan Keuntungan 10.0% x D | H18: =$Q$8 | J18: =J17*H18
C19: F | D19: Harga Satuan Pekerjaan (D+E) | J19: =SUM(J17:J18)
C21: H.2 | D21: Bahan Penutup (Sealant) | F21: Kilogram | K21: =ROUNDDOWN(J37,0) | M21: 8.1.(2)
C22: No | D22: Uraian | E22: Kode | F22: Sat. | G22: Koefisien | H22: Harga Satuan (Rp) | J22: Jumlah Harga (Rp)
C23: A | D23: TENAGA KERJA
C24: 1 | D24: Pekerja | E24: L01 | F24: jam | G24: 0.3860117 | H24: =VLOOKUP(D24,upahbahan,3,FALSE) | J24: =G24*H24
C25: 2 | D25: Mandor | E25: L03 | F25: jam | G25: 0.077202273 | H25: =VLOOKUP(D25,upahbahan,3,FALSE) | J25: =G25*H25
C26: JUMLAH HARGA TENAGA KERJA | J26: =SUM(J24:J25)
C27: B | D27: BAHAN
C28: 1 | D28: Sealant | E28: M126 | F28: Kg | G28: 1.02 | H28: =VLOOKUP(D28,upahbahan,3,FALSE) | J28: =G28*H28
C29: JUMLAH HARGA BAHAN | J29: =SUM(J28:J28)
C30: C | D30: PERALATAN
C31: 1 | D31: Gerinda Tangan GWS 750-10 | E31: E69 | F31: jam | G31: 0.077202244 | H31: =VLOOKUP(D31,upahbahan,3,FALSE) | J31: =G31*H31
C32: 2 | D32: Mini Generator Set 2000 Watt | E32: E98g | F32: jam | G32: 0.07720225 | H32: =VLOOKUP(D32,upahbahan,3,FALSE) | J32: =G32*H32
C33: 3 | D33: Alat Bantu | F33: Ls | G33: 1 | H33: =VLOOKUP(D33,upahbahan,3,FALSE) | J33: =G33*H33
C34: JUMLAH HARGA PERALATAN | J34: =SUM(J31:J33)
C35: D | D35: Jumlah (A+B+C) | J35: =J26+J29+J34
C36: E | D36: Biaya Umum dan Keuntungan 10.0% x D | H36: =$Q$8 | J36: =J35*H36
C37: F | D37: Harga Satuan Pekerjaan (D+E) | J37: =SUM(J35:J36)
C39: H.3 | D39: Tabung Penyuntik, Penyediaan dan Pemasangan | F39: Buah | K39: =ROUNDDOWN(J55,0) | M39: 8.1.(3)
C40: No | D40: Uraian | E40: Kode | F40: Sat. | G40: Koefisien | H40: Harga Satuan (Rp) | J40: Jumlah Harga (Rp)
C41: A | D41: TENAGA KERJA
C42: 1 | D42: Pekerja | E42: L01 | F42: jam | G42: 0.30120491 | H42: =VLOOKUP(D42,upahbahan,3,FALSE) | J42: =G42*H42
C43: 2 | D43: Mandor | E43: L03 | F43: jam | G43: 0.060240834 | H43: =VLOOKUP(D43,upahbahan,3,FALSE) | J43: =G43*H43
...

Sheet I - Harian dan Pekerjaan Lain-l
C2: I.1 | D2: Mandor | F2: Jam | K2: =ROUNDDOWN(J13,0) | M2: 9.1.(1)
C3: No | D3: Uraian | E3: Kode | F3: Sat. | G3: Koefisien | H3: Harga Satuan (Rp) | J3: Jumlah Harga (Rp)
C4: A | D4: TENAGA KERJA
C5: 1 | D5: Mandor | E5: L03 | F5: jam | G5: 1 | H5: =VLOOKUP(D5,upahbahan,3,FALSE) | J5: =G5*H5
C6: JUMLAH HARGA TENAGA KERJA | J6: =SUM(J5:J5)
C7: B | D7: BAHAN | N7: Catatan:
C8: JUMLAH HARGA BAHAN | J8: 0 | N8: Biaya Umum dan Keuntungan | O8: 0.1 | Q8: 0.1
C9: C | D9: PERALATAN
C10: JUMLAH HARGA PERALATAN | J10: 0
C11: D | D11: Jumlah (A+B+C) | J11: =J6+J8+J10
C12: E | D12: Biaya Umum dan Keuntungan 10.0% x D | H12: =$Q$8 | J12: =J11*H12
C13: F | D13: Harga Satuan Pekerjaan (D+E) | J13: =SUM(J11:J12)
C15: I.2 | D15: Pekerja Biasa | F15: Jam | K15: =ROUNDDOWN(J26,0) | M15: 9.1.(2)
C16: No | D16: Uraian | E16: Kode | F16: Sat. | G16: Koefisien | H16: Harga Satuan (Rp) | J16: Jumlah Harga (Rp)
C17: A | D17: BAHAN
C18: JUMLAH HARGA BAHAN | J18: 0
C19: B | D19: PERALATAN
C20: JUMLAH HARGA PERALATAN | J20: 0
C21: C | D21: BIAYA MANDOR PER BULAN
C22: 1 | D22: Pekerja Biasa - - - | E22: L01 | F22: jam | G22: 1 | H22: =VLOOKUP(D22,upahbahan,3,FALSE) | J22: =G22*H22
C23: JUMLAH HARGA BIAYA MANDOR PER BULAN | J23: =SUM(J22:J22)
C24: D | D24: Jumlah (A+B+C) | J24: =J18+J20+J23
C25: E | D25: Biaya Umum dan Keuntungan 10.0% x D | H25: =$Q$8 | J25: =J24*H25
C26: F | D26: Harga Satuan Pekerjaan (D+E) | J26: =SUM(J24:J25)
C28: I.3 | D28: Tukang Kayu, Tukang Batu, dan sebagainya | F28: Jam | K28: =ROUNDDOWN(J39,0) | M28: 9.1.(3)
C29: No | D29: Uraian | E29: Kode | F29: Sat. | G29: Koefisien | H29: Harga Satuan (Rp) | J29: Jumlah Harga (Rp)
C30: A | D30: BAHAN
C31: JUMLAH HARGA BAHAN | J31: 0
C32: B | D32: PERALATAN
C33: JUMLAH HARGA PERALATAN | J33: 0
C34: C | D34: BIAYA MANDOR PER BULAN
C35: 1 | D35: Tukang Kayu, Tukang Ba (L02) - | F35: jam | G35: 1 | H35: =VLOOKUP(D35,upahbahan,3,FALSE) | J35: =G35*H35
C36: JUMLAH HARGA BIAYA MANDOR PER BULAN | J36: =SUM(J35:J35)
C37: D | D37: Jumlah (A+B+C) | J37: =J31+J33+J36
C38: E | D38: Biaya Umum dan Keuntungan 10.0% x D | H38: =$Q$8 | J38: =J37*H38
C39: F | D39: Harga Satuan Pekerjaan (D+E) | J39: =SUM(J37:J38)
C41: I.4 | D41: Dump Truck, kapasitas nominal 4 ton | F41: Jam | K41: =ROUNDDOWN(J52,0) | M41: 9.1.(4a)
C42: No | D42: Uraian | E42: Kode | F42: Sat. | G42: Koefisien | H42: Harga Satuan (Rp) | J42: Jumlah Harga (Rp)
C43: A | D43: TENAGA KERJA
C44: JUMLAH HARGA TENAGA KERJA | J44: 0
...

Sheet J - Pemeliharaan
C2: J.1 | D2: Galian pada Saluran Air atau Lereng untuk Pemeliharaan | F2: Meter Kubik | K2: =ROUNDDOWN(J17,0) | M2: 10.1.(1)
C3: No | D3: Uraian | E3: Kode | F3: Sat. | G3: Koefisien | H3: Harga Satuan (Rp) | J3: Jumlah Harga (Rp)
C4: A | D4: TENAGA KERJA
C5: 1 | D5: Pekerja | E5: L01 | F5: jam | G5: 0.050362942 | H5: =VLOOKUP(D5,upahbahan,3,FALSE) | J5: =G5*H5
C6: 2 | D6: Mandor | E6: L03 | F6: jam | G6: 0.0038742074 | H6: =VLOOKUP(D6,upahbahan,3,FALSE) | J6: =G6*H6
C7: JUMLAH HARGA TENAGA KERJA | J7: =SUM(J5:J6) | N7: Catatan:
C8: B | D8: BAHAN | N8: Biaya Umum dan Keuntungan | O8: 0.1 | Q8: 0.1
C9: JUMLAH HARGA BAHAN | J9: 0
C10: C | D10: PERALATAN
C11: 1 | D11: Mini Excavator | E11: E10a | F11: jam | G11: 0.038740664 | H11: =VLOOKUP(D11,upahbahan,3,FALSE) | J11: =G11*H11
C12: 2 | D12: DUMP TRUCK 4 TON; 134 HP | E12: E08 | F12: jam | G12: 0.12082927 | H12: =VLOOKUP(D12,upahbahan,3,FALSE) | J12: =G12*H12
C13: 3 | D13: Alat Bantu | F13: Ls | G13: 1 | H13: =VLOOKUP(D13,upahbahan,3,FALSE) | J13: =G13*H13
C14: JUMLAH HARGA PERALATAN | J14: =SUM(J11:J13)
C15: D | D15: Jumlah (A+B+C) | J15: =J7+J9+J14
C16: E | D16: Biaya Umum dan Keuntungan 10.0% x D | H16: =$Q$8 | J16: =J15*H16
C17: F | D17: Harga Satuan Pekerjaan (D+E) | J17: =SUM(J15:J16)
C19: J.2 | D19: Timbunan Pilihan pada Lereng Tepi Saluran untuk Pemeliharaan | F19: Meter Kubik | K19: =ROUNDDOWN(J37,0) | M19: 10.1.(2)
C20: No | D20: Uraian | E20: Kode | F20: Sat. | G20: Koefisien | H20: Harga Satuan (Rp) | J20: Jumlah Harga (Rp)
C21: A | D21: TENAGA KERJA
C22: 1 | D22: Pekerja | E22: L01 | F22: Jam | G22: 0.82980762 | H22: =VLOOKUP(D22,upahbahan,3,FALSE) | J22: =G22*H22
C23: 2 | D23: Mandor | E23: L03 | F23: Jam | G23: 0.27660238 | H23: =VLOOKUP(D23,upahbahan,3,FALSE) | J23: =G23*H23
C24: JUMLAH HARGA TENAGA KERJA | J24: =SUM(J22:J23)
C25: B | D25: BAHAN
C26: 1 | D26: Bahan pilihan | E26: M09 | F26: M3 | G26: 1.26 | H26: =VLOOKUP(D26,upahbahan,3,FALSE) | J26: =G26*H26
C27: JUMLAH HARGA BAHAN | J27: =SUM(J26:J26)
C28: C | D28: PERALATAN
C29: 1 | D29: Excavator | E29: E10 | F29: Jam | G29: 0.0090685256 | H29: =VLOOKUP(D29,upahbahan,3,FALSE) | J29: =G29*H29
C30: 2 | D30: DUMP TRUCK 4 TON; 134 HP | E30: E08 | F30: Jam | G30: 0.27660248 | H30: =VLOOKUP(D30,upahbahan,3,FALSE) | J30: =G30*H30
C31: 3 | D31: Baby Vibratory Roller | E31: E19a | F31: Jam | G31: 0.074946432 | H31: =VLOOKUP(D31,upahbahan,3,FALSE) | J31: =G31*H31
C32: 4 | D32: Water Tank Truck | E32: E23 | F32: Jam | G32: 0.0070281224 | H32: =VLOOKUP(D32,upahbahan,3,FALSE) | J32: =G32*H32
C33: 5 | D33: Alat Bantu | F33: Ls | G33: 1 | H33: =VLOOKUP(D33,upahbahan,3,FALSE) | J33: =G33*H33
C34: JUMLAH HARGA PERALATAN | J34: =SUM(J29:J33)
C35: D | D35: Jumlah (A+B+C) | J35: =J24+J27+J34
C36: E | D36: Biaya Umum dan Keuntungan 10.0% x D | H36: =$Q$8 | J36: =J35*H36
C37: F | D37: Harga Satuan Pekerjaan (D+E) | J37: =SUM(J35:J36)
C39: J.3 | D39: Perbaikan Pasangan Batu dengan Mortar | F39: Meter Kubik | K39: =ROUNDDOWN(J60,0) | M39: 10.1.(3)
C40: No | D40: Uraian | E40: Kode | F40: Sat. | G40: Koefisien | H40: Harga Satuan (Rp) | J40: Jumlah Harga (Rp)
C41: A | D41: TENAGA KERJA
C42: 1 | D42: Pekerja | E42: L01 | F42: jam | G42: 1.9277108 | H42: =VLOOKUP(D42,upahbahan,3,FALSE) | J42: =G42*H42
C43: 2 | D43: Tukang Batu | E43: L02 | F43: jam | G43: 0.96385541 | H43: =VLOOKUP(D43,upahbahan,3,FALSE) | J43: =G43*H43
...

Sheet Info Sumber
B2: INFORMASI SUMBER & VERIFIKASI
B4: Dokumen sumber | C4: 5.-Lampiran-V-Bidang-Bina-Marga-ok.pdf (3.125 halaman)
B5: Dasar hukum | C5: SE Direktur Jenderal Bina Konstruksi No. 47/SE/Dk/2026
B6: Lampiran | C6: Lampiran V - Contoh AHSP Bidang Bina Marga (informatif)
B7: Jumlah mata pembayaran | C7: 1137 (Lampiran A-J)
B8: Blok analisa berharga | C8: 1116
B9: Mata pembayaran tanpa analisa | C9: 21 (halaman kosong / lump-sum)
B10: Baris harga satuan dasar | C10: 1339
B11: Named range | C11: upahbahan = 'Upah Bahan'!$F$10:$H$1348
B12: Catatan selisih sumber | C12: 10 blok ditandai 'cek: sumber Rp ...' pada kolom I
B14: Arsitektur rumus (sama dengan 'ahsp bina kontruksi 2026.xlsx')
B15: Harga satuan komponen | C15: =VLOOKUP(D<baris>,upahbahan,3,FALSE)
B16: Jumlah harga komponen | C16: =G<baris>*H<baris>
B17: Subtotal per kelompok | C17: =SUM(J<awal>:J<akhir>)
B18: D Jumlah (A+B+C) | C18: =J<subA>+J<subB>+J<subC>
B19: E Biaya Umum & Keuntungan | C19: H=$Q$8 (10%), J==J<D>*H<E>
B20: F Harga Satuan Pekerjaan | C20: =SUM(J<D>:J<E>)
B21: K harga dibulatkan (dipakai DHSP) | C21: =ROUNDDOWN(J<F>,0)
B23: Metode ekstraksi
B24: Format angka | C24: dua format dalam satu PDF: 27.643,54 (Indonesia) dan 27,643.54 (Inggris) - dideteksi per halaman
B25: Format tabel | C25: tabel A/B/C/D/E/F standar + varian C/D/E/F/G/H (metode pelaksanaan)
B26: Verifikasi | C26: subtotal tiap kelompok direkonsiliasi dengan total cetak; 1.116/1.127 halaman rekapitulasi konsisten 100%
